Workbook

Sheet Home
C3: Scarlet Violet Singles Pokemon Draft League | E3: =Source!$K$3 | F3: =Source!$K$4 | G3: =Source!$K$5 | H3: =Source!$K$6
C4: Year 2 | E4: =Source!$G$3 -> Ryan Tidey | F4: =Source!$G$4 -> Marcus | G4: =Source!$G$5 -> Ian Heslin | H4: =Source!$G$6 -> Ryan Evans
E5: =Source!$K$7 | F5: =Source!$K$8 | G5: =Source!$K$9 | H5: =Source!$K$10
E6: =Source!$G$7 -> Tyler Gottfredsen | F6: =Source!$G$8 -> Dick Hansen | G6: =Source!$G$9 -> Jackson McLoughlin | H6: =Source!$G$10 -> Zach VanSickle

Sheet Rules
A1: vvvvvvvvvvvvvv
E3: WPF Weather Division Rules
C5: League Rules
C6: # 1 | D6: 🟍 The season will be 7 weeks. You will play everyone once.
C7: # 2 | D7: 🟍 All matches must be played in the "Anything Goes" on https://play.pokemonshowdown.com/
C8: # 3 | D8: 🟍 Any additional questions may be asked in the Pokemon League Discord. Please @authorzed.
C10: Drafting Rules
C11: # 1 | D11: 🟍 Drafting will be the standard snake style, from 1-8 then again from 8 back to 1.
C12: 2 | D12: 🟍 Coaches have 125 points to draft 10-12 pokemon on their team.
C13: 3 | D13: 🟍 Species clause is in effect: You may not draft 2 pokemon of the same species (Ex: two Rotoms, Aegislash & Doublade)
C14: 4 | D14: 🟍 There will be a 24 hour grace period that starts immediately after the draft concludes.
C15: #5 | D15: 🟍 The move last respects is banned. Revival blessing may only be used once per battle.
C16: #6 | D16: 🟍 Each team is allowed to have 2-3 tera captains. Tera captains can have 3 tera types (1 of their normal types and any 2 other types)
C18: Season Rules
C19: # 1 | D19: 🟍 Coaches are allowed 8 FA transactions throughout the season once the grace period has concluded. Coach to coach trades are infinite.
C20: # 2 | D20: 🟍 Coaches are no longer able to use FA transactions after week 7 has concluded. Rosters become frozen before playoffs.
C21: # 3 | D21: 🟍 The top 8 teams at the end of the regular season will progress to playoffs.
C22: # 4 | D22: 🟍 When determining playoff seeding, the following measure will be used: Series Wins>Game Wins>Differential> Head-to-Head>Strength of Schedule. | H22: vvvvvvvvvvvvvvvvvvvvvvv
C24: Battle Rules
C25: # 1 | D25: 🟍 Battles are to be done every other week. Please coordinate with you opponet for the week through text or discord.
C26: # 2 | D26: 🟍 Evasion boosting and intentionally lowering your opponent's accuracy is not allowed. This includes snow cloak/sand veil.
C27: # 3 | D27: 🟍 All pokemon will be set to level 100.
C28: # 4 | D28: 🟍 Item clause is in effect for all battles. Berserk Gene, non-normal gems, mega stones, and Z-Crystals are banned.
C29: # 5 | D29: 🟍 Battle timer may be turned on by either coach for any reason. That coach is under no obligation to turn off timer unless their opponent disconnects unexpectantly. If this should happen, contact an online mod who will make the timer decision on your behalf. | H29: vv
C30: # 6 | D30: 🟍 All other Smogon clauses are in effect.
C31: # 7 | D31: 🟍 Dry baton pass is allowed. Positive stats or substitues may not be passed. You may use baton pass with wish.
C32: # 8 | D32: 🟍 Mega Stones, Z-Moves, and Dynamaxing are not allowed.
C33: # 9 | D33: 🟍 All unreleased items, such as type gems and berries, are not allowed. (Normal Gem is allowed)
C34: # 10 | D34: 🟍 Moody is banned

Sheet Draft Board
A1: zazzz
C3: Banned | F3: 19 Points | K3: 18 Points | P3: 17 Points | U3: 16 Points | Z3: 15 Points | AE3: 14 Points | AJ3: 13 Points | AO3: 12 Points | AT3: 11 Points | AW3: T | AY3: 10 Points | BB3: T | BD3: 9 Points | BG3: T | BI3: 8 Points | BL3: T | BN3: 7 Points | BQ3: T | BS3: 6 Points | BV3: T | BX3: 5 Points | CA3: T | CC3: 4 Points | CF3: T | CH3: 3 Points | CK3: T | CM3: 2 Points | CP3: T | CR3: 1 Points | CU3: T
C5: {=IFERROR(VLOOKUP(D5:D353,{Pokedex!$I$2:$I353,Pokedex!$H$2:$H353},2,FALSE),"")} | D5: Arceus | F5: =IFERROR(__xludf.DUMMYFUNCTION("IFERROR(SORT(FILTER(Source!$A$2:$B353,Source!$C$2:$C353=SPLIT(F3,"" Points"")),2,TRUE),"""")"),"") | G5: =IFERROR(__xludf.DUMMYFUNCTION("""COMPUTED_VALUE"""),"Chien-Pao") -> Chien-Pao | H5: {=IFS(G5:G353="","",COUNTIF(SUBSTITUTE(Data!$F$4:$F$100," (T)",""),G5:G353)>0,"X",1,"-")} -> X | K5: =IFERROR(__xludf.DUMMYFUNCTION("IFERROR(SORT(FILTER(Source!$A$2:$B353,Source!$C$2:$C353=SPLIT(K3,"" Points"")),2,TRUE),"""")"),"") | L5: =IFERROR(__xludf.DUMMYFUNCTION("""COMPUTED_VALUE"""),"Garchomp") -> Garchomp | M5: {=IFS(L5:L353="","",COUNTIF(SUBSTITUTE(Data!$F$4:$F$100," (T)",""),L5:L353)>0,"X",1,"-")} -> X | P5: =IFERROR(__xludf.DUMMYFUNCTION("IFERROR(SORT(FILTER(Source!$A$2:$B353,Source!$C$2:$C353=SPLIT(P3,"" Points"")),2,TRUE),"""")"),"") | Q5: =IFERROR(__xludf.DUMMYFUNCTION("""COMPUTED_VALUE"""),"Chi-Yu") -> Chi-Yu | R5: {=IFS(Q5:Q353="","",COUNTIF(SUBSTITUTE(Data!$F$4:$F$100," (T)",""),Q5:Q353)>0,"X",1,"-")} -> - | U5: =IFERROR(__xludf.DUMMYFUNCTION("IFERROR(SORT(FILTER(Source!$A$2:$B353,Source!$C$2:$C353=SPLIT(U3,"" Points"")),2,TRUE),"""")"),"") | V5: =IFERROR(__xludf.DUMMYFUNCTION("""COMPUTED_VALUE"""),"Blaziken") -> Blaziken | W5: {=IFS(V5:V353="","",COUNTIF(SUBSTITUTE(Data!$F$4:$F$100," (T)",""),V5:V353)>0,"X",1,"-")} -> X | Z5: =IFERROR(__xludf.DUMMYFUNCTION("IFERROR(SORT(FILTER(Source!$A$2:$B353,Source!$C$2:$C353=SPLIT(Z3,"" Points"")),2,TRUE),"""")"),"") | AA5: =IFERROR(__xludf.DUMMYFUNCTION("""COMPUTED_VALUE"""),"Baxcalibur") -> Baxcalibur | AB5: {=IFS(AA5:AA353="","",COUNTIF(SUBSTITUTE(Data!$F$4:$F$100," (T)",""),AA5:AA353)>0,"X",1,"-")} -> - | AE5: =IFERROR(__xludf.DUMMYFUNCTION("IFERROR(SORT(FILTER(Source!$A$2:$B353,Source!$C$2:$C353=SPLIT(AE3,"" Points"")),2,TRUE),"""")"),"") | AF5: =IFERROR(__xludf.DUMMYFUNCTION("""COMPUTED_VALUE"""),"Annihilape") -> Annihilape | AG5: {=IFS(AF5:AF353="","",COUNTIF(SUBSTITUTE(Data!$F$4:$F$100," (T)",""),AF5:AF353)>0,"X",1,"-")} -> X | AJ5: =IFERROR(__xludf.DUMMYFUNCTION("IFERROR(SORT(FILTER(Source!$A$2:$B353,Source!$C$2:$C353=SPLIT(AJ3,"" Points"")),2,TRUE),"""")"),"") | AK5: =IFERROR(__xludf.DUMMYFUNCTION("""COMPUTED_VALUE"""),"Azumarill") -> Azumarill | AL5: {=IFS(AK5:AK353="","",COUNTIF(SUBSTITUTE(Data!$F$4:$F$100," (T)",""),AK5:AK353)>0,"X",1,"-")} -> - | AO5: =IFERROR(__xludf.DUMMYFUNCTION("IFERROR(SORT(FILTER(Source!$A$2:$B353,Source!$C$2:$C353=SPLIT(AO3,"" Points"")),2,TRUE),"""")"),"") | AP5: =IFERROR(__xludf.DUMMYFUNCTION("""COMPUTED_VALUE"""),"Ceruledge") -> Ceruledge | AQ5: {=IFS(AP5:AP353="","",COUNTIF(SUBSTITUTE(Data!$F$4:$F$100," (T)",""),AP5:AP353)>0,"X",1,"-")} -> - | AT5: =IFERROR(__xludf.DUMMYFUNCTION("IFERROR(SORT(FILTER(Source!$A$2:$B353,Source!$C$2:$C353=SPLIT(AT3,"" Points"")),2,TRUE),"""")"),"") | AU5: =IFERROR(__xludf.DUMMYFUNCTION("""COMPUTED_VALUE"""),"Alolan Ninetales") -> Alolan Ninetales | AV5: {=IFS(AU5:AU353="","",COUNTIF(SUBSTITUTE(Data!$F$4:$F$100," (T)",""),AU5:AU353)>0,"X",1,"-")} -> - | AW5: {=IFERROR(VLOOKUP(AU5:AU353,Source!$B$3:$D353,3,FALSE),"")} -> 12 | AY5: =IFERROR(__xludf.DUMMYFUNCTION("IFERROR(SORT(FILTER(Source!$A$2:$B353,Source!$C$2:$C353=SPLIT(AY3,"" Points"")),2,TRUE),"""")"),"") | AZ5: =IFERROR(__xludf.DUMMYFUNCTION("""COMPUTED_VALUE"""),"Alolan Muk") -> Alolan Muk | BA5: {=IFS(AZ5:AZ353="","",COUNTIF(SUBSTITUTE(Data!$F$4:$F$100," (T)",""),AZ5:AZ353)>0,"X",1,"-")} -> - | BB5: {=IFERROR(VLOOKUP(AZ5:AZ353,Source!$B$3:$D353,3,FALSE),"")} -> 11 | BD5: =IFERROR(__xludf.DUMMYFUNCTION("IFERROR(SORT(FILTER(Source!$A$2:$B353,Source!$C$2:$C353=SPLIT(BD3,"" Points"")),2,TRUE),"""")"),"") | BE5: =IFERROR(__xludf.DUMMYFUNCTION("""COMPUTED_VALUE"""),"Amoonguss") -> Amoonguss | BF5: {=IFS(BE5:BE353="","",COUNTIF(SUBSTITUTE(Data!$F$4:$F$100," (T)",""),BE5:BE353)>0,"X",1,"-")} -> - | BG5: {=IFERROR(VLOOKUP(BE5:BE353,Source!$B$3:$D353,3,FALSE),"")} -> 10 | BI5: =IFERROR(__xludf.DUMMYFUNCTION("IFERROR(SORT(FILTER(Source!$A$2:$B353,Source!$C$2:$C353=SPLIT(BI3,"" Points"")),2,TRUE),"""")"),"") | BJ5: =IFERROR(__xludf.DUMMYFUNCTION("""COMPUTED_VALUE"""),"Armarouge") -> Armarouge | BK5: {=IFS(BJ5:BJ353="","",COUNTIF(SUBSTITUTE(Data!$F$4:$F$100," (T)",""),BJ5:BJ353)>0,"X",1,"-")} -> - | BL5: {=IFERROR(VLOOKUP(BJ5:BJ353,Source!$B$3:$D353,3,FALSE),"")} -> 10 | BN5: =IFERROR(__xludf.DUMMYFUNCTION("IFERROR(SORT(FILTER(Source!$A$2:$B353,Source!$C$2:$C353=SPLIT(BN3,"" Points"")),2,TRUE),"""")"),"") | BO5: =IFERROR(__xludf.DUMMYFUNCTION("""COMPUTED_VALUE"""),"Abomasnow") -> Abomasnow | BP5: {=IFS(BO5:BO353="","",COUNTIF(SUBSTITUTE(Data!$F$4:$F$100," (T)",""),BO5:BO353)>0,"X",1,"-")} -> - | BQ5: {=IFERROR(VLOOKUP(BO5:BO353,Source!$B$3:$D353,3,FALSE),"")} -> 8 | BS5: =IFERROR(__xludf.DUMMYFUNCTION("IFERROR(SORT(FILTER(Source!$A$2:$B353,Source!$C$2:$C353=SPLIT(BS3,"" Points"")),2,TRUE),"""")"),"") | BT5: =IFERROR(__xludf.DUMMYFUNCTION("""COMPUTED_VALUE"""),"Barraskewda") -> Barraskewda | BU5: {=IFS(BT5:BT353="","",COUNTIF(SUBSTITUTE(Data!$F$4:$F$100," (T)",""),BT5:BT353)>0,"X",1,"-")} -> - | BV5: {=IFERROR(VLOOKUP(BT5:BT353,Source!$B$3:$D353,3,FALSE),"")} -> 7 | BX5: =IFERROR(__xludf.DUMMYFUNCTION("IFERROR(SORT(FILTER(Source!$A$2:$B353,Source!$C$2:$C353=SPLIT(BX3,"" Points"")),2,TRUE),"""")"),"") | BY5: =IFERROR(__xludf.DUMMYFUNCTION("""COMPUTED_VALUE"""),"Alolan Persian") -> Alolan Persian | BZ5: {=IFS(BY5:BY353="","",COUNTIF(SUBSTITUTE(Data!$F$4:$F$100," (T)",""),BY5:BY353)>0,"X",1,"-")} -> - | CA5: {=IFERROR(VLOOKUP(BY5:BY353,Source!$B$3:$D353,3,FALSE),"")} -> 6 | CC5: =IFERROR(__xludf.DUMMYFUNCTION("IFERROR(SORT(FILTER(Source!$A$2:$B353,Source!$C$2:$C353=SPLIT(CC3,"" Points"")),2,TRUE),"""")"),"") | CD5: =IFERROR(__xludf.DUMMYFUNCTION("""COMPUTED_VALUE"""),"Altaria") -> Altaria | CE5: {=IFS(CD5:CD353="","",COUNTIF(SUBSTITUTE(Data!$F$4:$F$100," (T)",""),CD5:CD353)>0,"X",1,"-")} -> - | CF5: {=IFERROR(VLOOKUP(CD5:CD353,Source!$B$3:$D353,3,FALSE),"")} -> 5 | CH5: =IFERROR(__xludf.DUMMYFUNCTION("IFERROR(SORT(FILTER(Source!$A$2:$B353,Source!$C$2:$C353=SPLIT(CH3,"" Points"")),2,TRUE),"""")"),"") | CI5: =IFERROR(__xludf.DUMMYFUNCTION("""COMPUTED_VALUE"""),"Alolan Exeggutor") -> Alolan Exeggutor | CJ5: {=IFS(CI5:CI353="","",COUNTIF(SUBSTITUTE(Data!$F$4:$F$100," (T)",""),CI5:CI353)>0,"X",1,"-")} -> - | CK5: {=IFERROR(VLOOKUP(CI5:CI353,Source!$B$3:$D353,3,FALSE),"")} -> 4 | CM5: =IFERROR(__xludf.DUMMYFUNCTION("IFERROR(SORT(FILTER(Source!$A$2:$B353,Source!$C$2:$C353=SPLIT(CM3,"" Points"")),2,TRUE),"""")"),"") | CN5: =IFERROR(__xludf.DUMMYFUNCTION("""COMPUTED_VALUE"""),"Alcremie") -> Alcremie | CO5: {=IFS(CN5:CN353="","",COUNTIF(SUBSTITUTE(Data!$F$4:$F$100," (T)",""),CN5:CN353)>0,"X",1,"-")} -> - | CP5: {=IFERROR(VLOOKUP(CN5:CN353,Source!$B$3:$D353,3,FALSE),"")} -> 3 | CR5: =IFERROR(__xludf.DUMMYFUNCTION("IFERROR(SORT(FILTER(Source!$A$2:$B353,Source!$C$2:$C353=SPLIT(CR3,"" Points"")),2,TRUE),"""")"),"") | CS5: =IFERROR(__xludf.DUMMYFUNCTION("""COMPUTED_VALUE"""),"Alolan Grimer") -> Alolan Grimer | CT5: {=IFS(CS5:CS353="","",COUNTIF(SUBSTITUTE(Data!$F$4:$F$100," (T)",""),CS5:CS353)>0,"X",1,"-")} -> - | CU5: {=IFERROR(VLOOKUP(CS5:CS353,Source!$B$3:$D353,3,FALSE),"")} -> 1
D6: Calyrex-Ice | F6: =IFERROR(__xludf.DUMMYFUNCTION("""COMPUTED_VALUE"""),"") | G6: =IFERROR(__xludf.DUMMYFUNCTION("""COMPUTED_VALUE"""),"Darkrai") -> Darkrai | H6: X | K6: =IFERROR(__xludf.DUMMYFUNCTION("""COMPUTED_VALUE"""),"") | L6: =IFERROR(__xludf.DUMMYFUNCTION("""COMPUTED_VALUE"""),"Great Tusk") -> Great Tusk | M6: X | P6: =IFERROR(__xludf.DUMMYFUNCTION("""COMPUTED_VALUE"""),"") | Q6: =IFERROR(__xludf.DUMMYFUNCTION("""COMPUTED_VALUE"""),"Deoxys-Speed") -> Deoxys-Speed | R6: X | U6: =IFERROR(__xludf.DUMMYFUNCTION("""COMPUTED_VALUE"""),"") | V6: =IFERROR(__xludf.DUMMYFUNCTION("""COMPUTED_VALUE"""),"Enamorus-Incarnate") -> Enamorus-Incarnate | W6: X | Z6: =IFERROR(__xludf.DUMMYFUNCTION("""COMPUTED_VALUE"""),"") | AA6: =IFERROR(__xludf.DUMMYFUNCTION("""COMPUTED_VALUE"""),"Dragonite") -> Dragonite | AB6: X | AE6: =IFERROR(__xludf.DUMMYFUNCTION("""COMPUTED_VALUE"""),"") | AF6: =IFERROR(__xludf.DUMMYFUNCTION("""COMPUTED_VALUE"""),"Cinderace") -> Cinderace | AG6: X | AJ6: =IFERROR(__xludf.DUMMYFUNCTION("""COMPUTED_VALUE"""),"") | AK6: =IFERROR(__xludf.DUMMYFUNCTION("""COMPUTED_VALUE"""),"Clefable") -> Clefable | AL6: X | AO6: =IFERROR(__xludf.DUMMYFUNCTION("""COMPUTED_VALUE"""),"") | AP6: =IFERROR(__xludf.DUMMYFUNCTION("""COMPUTED_VALUE"""),"Deoxys-Defense") -> Deoxys-Defense | AQ6: - | AT6: =IFERROR(__xludf.DUMMYFUNCTION("""COMPUTED_VALUE"""),"") | AU6: =IFERROR(__xludf.DUMMYFUNCTION("""COMPUTED_VALUE"""),"Archaludon") -> Archaludon | AV6: X | AW6: 12 | AY6: =IFERROR(__xludf.DUMMYFUNCTION("""COMPUTED_VALUE"""),"") | AZ6: =IFERROR(__xludf.DUMMYFUNCTION("""COMPUTED_VALUE"""),"Alomomola") -> Alomomola | BA6: X | BB6: 11 | BD6: =IFERROR(__xludf.DUMMYFUNCTION("""COMPUTED_VALUE"""),"") | BE6: =IFERROR(__xludf.DUMMYFUNCTION("""COMPUTED_VALUE"""),"Breloom") -> Breloom | BF6: - | BG6: 10 | BI6: =IFERROR(__xludf.DUMMYFUNCTION("""COMPUTED_VALUE"""),"") | BJ6: =IFERROR(__xludf.DUMMYFUNCTION("""COMPUTED_VALUE"""),"Braviary") -> Braviary | BK6: - | BL6: 9 | BN6: =IFERROR(__xludf.DUMMYFUNCTION("""COMPUTED_VALUE"""),"") | BO6: =IFERROR(__xludf.DUMMYFUNCTION("""COMPUTED_VALUE"""),"Araquanid") -> Araquanid | BP6: - | BQ6: 9 | BS6: =IFERROR(__xludf.DUMMYFUNCTION("""COMPUTED_VALUE"""),"") | BT6: =IFERROR(__xludf.DUMMYFUNCTION("""COMPUTED_VALUE"""),"Bellibolt") -> Bellibolt | BU6: - | BV6: 8 | BX6: =IFERROR(__xludf.DUMMYFUNCTION("""COMPUTED_VALUE"""),"") | BY6: =IFERROR(__xludf.DUMMYFUNCTION("""COMPUTED_VALUE"""),"Alolan Raichu") -> Alolan Raichu | BZ6: - | CA6: 6 | CC6: =IFERROR(__xludf.DUMMYFUNCTION("""COMPUTED_VALUE"""),"") | CD6: =IFERROR(__xludf.DUMMYFUNCTION("""COMPUTED_VALUE"""),"Appletun") -> Appletun | CE6: - | CF6: 5 | CH6: =IFERROR(__xludf.DUMMYFUNCTION("""COMPUTED_VALUE"""),"") | CI6: =IFERROR(__xludf.DUMMYFUNCTION("""COMPUTED_VALUE"""),"Alolan Sandslash") -> Alolan Sandslash | CJ6: - | CK6: 4 | CM6: =IFERROR(__xludf.DUMMYFUNCTION("""COMPUTED_VALUE"""),"") | CN6: =IFERROR(__xludf.DUMMYFUNCTION("""COMPUTED_VALUE"""),"Alolan Dugtrio") -> Alolan Dugtrio | CO6: - | CP6: 3 | CR6: =IFERROR(__xludf.DUMMYFUNCTION("""COMPUTED_VALUE"""),"") | CS6: =IFERROR(__xludf.DUMMYFUNCTION("""COMPUTED_VALUE"""),"Alolan Meowth") -> Alolan Meowth | CT6: - | CU6: 1
D7: Calyrex-Shadow | F7: =IFERROR(__xludf.DUMMYFUNCTION("""COMPUTED_VALUE"""),"") | G7: =IFERROR(__xludf.DUMMYFUNCTION("""COMPUTED_VALUE"""),"Dragapult") -> Dragapult | H7: X | K7: =IFERROR(__xludf.DUMMYFUNCTION("""COMPUTED_VALUE"""),"") | L7: =IFERROR(__xludf.DUMMYFUNCTION("""COMPUTED_VALUE"""),"Palafin") -> Palafin | M7: X | P7: =IFERROR(__xludf.DUMMYFUNCTION("""COMPUTED_VALUE"""),"") | Q7: =IFERROR(__xludf.DUMMYFUNCTION("""COMPUTED_VALUE"""),"Greninja") -> Greninja | R7: - | U7: =IFERROR(__xludf.DUMMYFUNCTION("""COMPUTED_VALUE"""),"") | V7: =IFERROR(__xludf.DUMMYFUNCTION("""COMPUTED_VALUE"""),"Gouging Fire") -> Gouging Fire | W7: X | Z7: =IFERROR(__xludf.DUMMYFUNCTION("""COMPUTED_VALUE"""),"") | AA7: =IFERROR(__xludf.DUMMYFUNCTION("""COMPUTED_VALUE"""),"Galarian Slowking") -> Galarian Slowking | AB7: X | AE7: =IFERROR(__xludf.DUMMYFUNCTION("""COMPUTED_VALUE"""),"") | AF7: =IFERROR(__xludf.DUMMYFUNCTION("""COMPUTED_VALUE"""),"Excadrill") -> Excadrill | AG7: - | AJ7: =IFERROR(__xludf.DUMMYFUNCTION("""COMPUTED_VALUE"""),"") | AK7: =IFERROR(__xludf.DUMMYFUNCTION("""COMPUTED_VALUE"""),"Corviknight") -> Corviknight | AL7: X | AO7: =IFERROR(__xludf.DUMMYFUNCTION("""COMPUTED_VALUE"""),"") | AP7: =IFERROR(__xludf.DUMMYFUNCTION("""COMPUTED_VALUE"""),"Galarian Moltres") -> Galarian Moltres | AQ7: - | AT7: =IFERROR(__xludf.DUMMYFUNCTION("""COMPUTED_VALUE"""),"") | AU7: =IFERROR(__xludf.DUMMYFUNCTION("""COMPUTED_VALUE"""),"Azelf") -> Azelf | AV7: X | AW7: 12 | AY7: =IFERROR(__xludf.DUMMYFUNCTION("""COMPUTED_VALUE"""),"") | AZ7: =IFERROR(__xludf.DUMMYFUNCTION("""COMPUTED_VALUE"""),"Arcanine") -> Arcanine | BA7: X | BB7: 11 | BD7: =IFERROR(__xludf.DUMMYFUNCTION("""COMPUTED_VALUE"""),"") | BE7: =IFERROR(__xludf.DUMMYFUNCTION("""COMPUTED_VALUE"""),"Bronzong") -> Bronzong | BF7: - | BG7: 10 | BI7: =IFERROR(__xludf.DUMMYFUNCTION("""COMPUTED_VALUE"""),"") | BJ7: =IFERROR(__xludf.DUMMYFUNCTION("""COMPUTED_VALUE"""),"Cetitan") -> Cetitan | BK7: - | BL7: 11 | BN7: =IFERROR(__xludf.DUMMYFUNCTION("""COMPUTED_VALUE"""),"") | BO7: =IFERROR(__xludf.DUMMYFUNCTION("""COMPUTED_VALUE"""),"Bisharp") -> Bisharp | BP7: X | BQ7: 9 | BS7: =IFERROR(__xludf.DUMMYFUNCTION("""COMPUTED_VALUE"""),"") | BT7: =IFERROR(__xludf.DUMMYFUNCTION("""COMPUTED_VALUE"""),"Cloyster") -> Cloyster | BU7: - | BV7: 8 | BX7: =IFERROR(__xludf.DUMMYFUNCTION("""COMPUTED_VALUE"""),"") | BY7: =IFERROR(__xludf.DUMMYFUNCTION("""COMPUTED_VALUE"""),"Arboliva") -> Arboliva | BZ7: - | CA7: 6 | CC7: =IFERROR(__xludf.DUMMYFUNCTION("""COMPUTED_VALUE"""),"") | CD7: =IFERROR(__xludf.DUMMYFUNCTION("""COMPUTED_VALUE"""),"Charizard") -> Charizard | CE7: - | CF7: 5 | CH7: =IFERROR(__xludf.DUMMYFUNCTION("""COMPUTED_VALUE"""),"") | CI7: =IFERROR(__xludf.DUMMYFUNCTION("""COMPUTED_VALUE"""),"Ambipom") -> Ambipom | CJ7: - | CK7: 4 | CM7: =IFERROR(__xludf.DUMMYFUNCTION("""COMPUTED_VALUE"""),"") | CN7: =IFERROR(__xludf.DUMMYFUNCTION("""COMPUTED_VALUE"""),"Alolan Golem") -> Alolan Golem | CO7: - | CP7: 3 | CR7: =IFERROR(__xludf.DUMMYFUNCTION("""COMPUTED_VALUE"""),"") | CS7: =IFERROR(__xludf.DUMMYFUNCTION("""COMPUTED_VALUE"""),"Alolan Vulpix") -> Alolan Vulpix | CT7: X | CU7: 2
D8: Dialga | F8: =IFERROR(__xludf.DUMMYFUNCTION("""COMPUTED_VALUE"""),"") | G8: =IFERROR(__xludf.DUMMYFUNCTION("""COMPUTED_VALUE"""),"Iron Valiant") -> Iron Valiant | H8: X | K8: =IFERROR(__xludf.DUMMYFUNCTION("""COMPUTED_VALUE"""),"") | L8: =IFERROR(__xludf.DUMMYFUNCTION("""COMPUTED_VALUE"""),"Spectrier") -> Spectrier | M8: X | P8: =IFERROR(__xludf.DUMMYFUNCTION("""COMPUTED_VALUE"""),"") | Q8: =IFERROR(__xludf.DUMMYFUNCTION("""COMPUTED_VALUE"""),"Latios") -> Latios | R8: - | U8: =IFERROR(__xludf.DUMMYFUNCTION("""COMPUTED_VALUE"""),"") | V8: =IFERROR(__xludf.DUMMYFUNCTION("""COMPUTED_VALUE"""),"Kyurem") -> Kyurem | W8: X | X8: - | Z8: =IFERROR(__xludf.DUMMYFUNCTION("""COMPUTED_VALUE"""),"") | AA8: =IFERROR(__xludf.DUMMYFUNCTION("""COMPUTED_VALUE"""),"Gholdengo") -> Gholdengo | AB8: - | AE8: =IFERROR(__xludf.DUMMYFUNCTION("""COMPUTED_VALUE"""),"") | AF8: =IFERROR(__xludf.DUMMYFUNCTION("""COMPUTED_VALUE"""),"Iron Moth") -> Iron Moth | AG8: - | AJ8: =IFERROR(__xludf.DUMMYFUNCTION("""COMPUTED_VALUE"""),"") | AK8: =IFERROR(__xludf.DUMMYFUNCTION("""COMPUTED_VALUE"""),"Cyclizar") -> Cyclizar | AL8: - | AO8: =IFERROR(__xludf.DUMMYFUNCTION("""COMPUTED_VALUE"""),"") | AP8: =IFERROR(__xludf.DUMMYFUNCTION("""COMPUTED_VALUE"""),"Gengar") -> Gengar | AQ8: - | AT8: =IFERROR(__xludf.DUMMYFUNCTION("""COMPUTED_VALUE"""),"") | AU8: =IFERROR(__xludf.DUMMYFUNCTION("""COMPUTED_VALUE"""),"Basculegion") -> Basculegion | AV8: X | AW8: 12 | AY8: =IFERROR(__xludf.DUMMYFUNCTION("""COMPUTED_VALUE"""),"") | AZ8: =IFERROR(__xludf.DUMMYFUNCTION("""COMPUTED_VALUE"""),"Cobalion") -> Cobalion | BA8: X | BB8: 11 | BD8: =IFERROR(__xludf.DUMMYFUNCTION("""COMPUTED_VALUE"""),"") | BE8: =IFERROR(__xludf.DUMMYFUNCTION("""COMPUTED_VALUE"""),"Clodsire") -> Clodsire | BF8: - | BG8: 10 | BI8: =IFERROR(__xludf.DUMMYFUNCTION("""COMPUTED_VALUE"""),"") | BJ8: =IFERROR(__xludf.DUMMYFUNCTION("""COMPUTED_VALUE"""),"Chesnaught") -> Chesnaught | BK8: - | BL8: 9 | BN8: =IFERROR(__xludf.DUMMYFUNCTION("""COMPUTED_VALUE"""),"") | BO8: =IFERROR(__xludf.DUMMYFUNCTION("""COMPUTED_VALUE"""),"Blissey") -> Blissey | BP8: - | BQ8: 8 | BS8: =IFERROR(__xludf.DUMMYFUNCTION("""COMPUTED_VALUE"""),"") | BT8: =IFERROR(__xludf.DUMMYFUNCTION("""COMPUTED_VALUE"""),"Drifblim") -> Drifblim | BU8: - | BV8: 7 | BX8: =IFERROR(__xludf.DUMMYFUNCTION("""COMPUTED_VALUE"""),"") | BY8: =IFERROR(__xludf.DUMMYFUNCTION("""COMPUTED_VALUE"""),"Bombirdier") -> Bombirdier | BZ8: - | CA8: 6 | CC8: =IFERROR(__xludf.DUMMYFUNCTION("""COMPUTED_VALUE"""),"") | CD8: =IFERROR(__xludf.DUMMYFUNCTION("""COMPUTED_VALUE"""),"Coalossal") -> Coalossal | CE8: X | CF8: 5 | CH8: =IFERROR(__xludf.DUMMYFUNCTION("""COMPUTED_VALUE"""),"") | CI8: =IFERROR(__xludf.DUMMYFUNCTION("""COMPUTED_VALUE"""),"Articuno") -> Articuno | CJ8: - | CK8: 4 | CM8: =IFERROR(__xludf.DUMMYFUNCTION("""COMPUTED_VALUE"""),"") | CN8: =IFERROR(__xludf.DUMMYFUNCTION("""COMPUTED_VALUE"""),"Ampharos") -> Ampharos | CO8: - | CP8: 3 | CR8: =IFERROR(__xludf.DUMMYFUNCTION("""COMPUTED_VALUE"""),"") | CS8: =IFERROR(__xludf.DUMMYFUNCTION("""COMPUTED_VALUE"""),"Ariados") -> Ariados | CT8: - | CU8: 2
D9: Eternatus | N9: - | P9: =IFERROR(__xludf.DUMMYFUNCTION("""COMPUTED_VALUE"""),"") | Q9: =IFERROR(__xludf.DUMMYFUNCTION("""COMPUTED_VALUE"""),"Tornadus-Therian") -> Tornadus-Therian | R9: X | U9: =IFERROR(__xludf.DUMMYFUNCTION("""COMPUTED_VALUE"""),"") | V9: =IFERROR(__xludf.DUMMYFUNCTION("""COMPUTED_VALUE"""),"Meowscarada") -> Meowscarada | W9: X | Z9: =IFERROR(__xludf.DUMMYFUNCTION("""COMPUTED_VALUE"""),"") | AA9: =IFERROR(__xludf.DUMMYFUNCTION("""COMPUTED_VALUE"""),"Hisuian Samurott") -> Hisuian Samurott | AB9: X | AE9: =IFERROR(__xludf.DUMMYFUNCTION("""COMPUTED_VALUE"""),"") | AF9: =IFERROR(__xludf.DUMMYFUNCTION("""COMPUTED_VALUE"""),"Jirachi") -> Jirachi | AG9: X | AJ9: =IFERROR(__xludf.DUMMYFUNCTION("""COMPUTED_VALUE"""),"") | AK9: =IFERROR(__xludf.DUMMYFUNCTION("""COMPUTED_VALUE"""),"Galarian Zapdos") -> Galarian Zapdos | AL9: - | AO9: =IFERROR(__xludf.DUMMYFUNCTION("""COMPUTED_VALUE"""),"") | AP9: =IFERROR(__xludf.DUMMYFUNCTION("""COMPUTED_VALUE"""),"Gliscor") -> Gliscor | AQ9: X | AT9: =IFERROR(__xludf.DUMMYFUNCTION("""COMPUTED_VALUE"""),"") | AU9: =IFERROR(__xludf.DUMMYFUNCTION("""COMPUTED_VALUE"""),"Blastoise") -> Blastoise | AV9: - | AW9: 13 | AY9: =IFERROR(__xludf.DUMMYFUNCTION("""COMPUTED_VALUE"""),"") | AZ9: =IFERROR(__xludf.DUMMYFUNCTION("""COMPUTED_VALUE"""),"Decidueye") -> Decidueye | BA9: - | BB9: 11 | BD9: =IFERROR(__xludf.DUMMYFUNCTION("""COMPUTED_VALUE"""),"") | BE9: =IFERROR(__xludf.DUMMYFUNCTION("""COMPUTED_VALUE"""),"Conkeldurr") -> Conkeldurr | BF9: - | BG9: 10 | BI9: =IFERROR(__xludf.DUMMYFUNCTION("""COMPUTED_VALUE"""),"") | BJ9: =IFERROR(__xludf.DUMMYFUNCTION("""COMPUTED_VALUE"""),"Comfey") -> Comfey | BK9: - | BL9: 12 | BN9: =IFERROR(__xludf.DUMMYFUNCTION("""COMPUTED_VALUE"""),"") | BO9: =IFERROR(__xludf.DUMMYFUNCTION("""COMPUTED_VALUE"""),"Brambleghast") -> Brambleghast | BP9: - | BQ9: 8 | BS9: =IFERROR(__xludf.DUMMYFUNCTION("""COMPUTED_VALUE"""),"") | BT9: =IFERROR(__xludf.DUMMYFUNCTION("""COMPUTED_VALUE"""),"Eelektross") -> Eelektross | BU9: - | BV9: 7 | BX9: =IFERROR(__xludf.DUMMYFUNCTION("""COMPUTED_VALUE"""),"") | BY9: =IFERROR(__xludf.DUMMYFUNCTION("""COMPUTED_VALUE"""),"Brute Bonnet") -> Brute Bonnet | BZ9: - | CA9: 6 | CC9: =IFERROR(__xludf.DUMMYFUNCTION("""COMPUTED_VALUE"""),"") | CD9: =IFERROR(__xludf.DUMMYFUNCTION("""COMPUTED_VALUE"""),"Cryogonal") -> Cryogonal | CE9: - | CF9: 5 | CH9: =IFERROR(__xludf.DUMMYFUNCTION("""COMPUTED_VALUE"""),"") | CI9: =IFERROR(__xludf.DUMMYFUNCTION("""COMPUTED_VALUE"""),"Avalugg") -> Avalugg | CJ9: - | CK9: 4 | CM9: =IFERROR(__xludf.DUMMYFUNCTION("""COMPUTED_VALUE"""),"") | CN9: =IFERROR(__xludf.DUMMYFUNCTION("""COMPUTED_VALUE"""),"Arbok") -> Arbok | CO9: - | CP9: 3 | CR9: =IFERROR(__xludf.DUMMYFUNCTION("""COMPUTED_VALUE"""),"") | CS9: =IFERROR(__xludf.DUMMYFUNCTION("""COMPUTED_VALUE"""),"Banette") -> Banette | CT9: - | CU9: 1
D10: Giratina | U10: =IFERROR(__xludf.DUMMYFUNCTION("""COMPUTED_VALUE"""),"") | V10: =IFERROR(__xludf.DUMMYFUNCTION("""COMPUTED_VALUE"""),"Sneasler") -> Sneasler | W10: X | Z10: =IFERROR(__xludf.DUMMYFUNCTION("""COMPUTED_VALUE"""),"") | AA10: =IFERROR(__xludf.DUMMYFUNCTION("""COMPUTED_VALUE"""),"Iron Boulder") -> Iron Boulder | AB10: X | AE10: =IFERROR(__xludf.DUMMYFUNCTION("""COMPUTED_VALUE"""),"") | AF10: =IFERROR(__xludf.DUMMYFUNCTION("""COMPUTED_VALUE"""),"Kingambit") -> Kingambit | AG10: - | AJ10: =IFERROR(__xludf.DUMMYFUNCTION("""COMPUTED_VALUE"""),"") | AK10: =IFERROR(__xludf.DUMMYFUNCTION("""COMPUTED_VALUE"""),"Glimmora") -> Glimmora | AL10: - | AO10: =IFERROR(__xludf.DUMMYFUNCTION("""COMPUTED_VALUE"""),"") | AP10: =IFERROR(__xludf.DUMMYFUNCTION("""COMPUTED_VALUE"""),"Grimmsnarl") -> Grimmsnarl | AQ10: X | AT10: =IFERROR(__xludf.DUMMYFUNCTION("""COMPUTED_VALUE"""),"") | AU10: =IFERROR(__xludf.DUMMYFUNCTION("""COMPUTED_VALUE"""),"Donphan") -> Donphan | AV10: - | AW10: 12 | AY10: =IFERROR(__xludf.DUMMYFUNCTION("""COMPUTED_VALUE"""),"") | AZ10: =IFERROR(__xludf.DUMMYFUNCTION("""COMPUTED_VALUE"""),"Empoleon") -> Empoleon | BA10: - | BB10: 11 | BD10: =IFERROR(__xludf.DUMMYFUNCTION("""COMPUTED_VALUE"""),"") | BE10: =IFERROR(__xludf.DUMMYFUNCTION("""COMPUTED_VALUE"""),"Cresselia") -> Cresselia | BF10: - | BG10: 12 | BI10: =IFERROR(__xludf.DUMMYFUNCTION("""COMPUTED_VALUE"""),"") | BJ10: =IFERROR(__xludf.DUMMYFUNCTION("""COMPUTED_VALUE"""),"Copperajah") -> Copperajah | BK10: - | BL10: 9 | BN10: =IFERROR(__xludf.DUMMYFUNCTION("""COMPUTED_VALUE"""),"") | BO10: =IFERROR(__xludf.DUMMYFUNCTION("""COMPUTED_VALUE"""),"Chandelure") -> Chandelure | BP10: - | BQ10: 8 | BS10: =IFERROR(__xludf.DUMMYFUNCTION("""COMPUTED_VALUE"""),"") | BT10: =IFERROR(__xludf.DUMMYFUNCTION("""COMPUTED_VALUE"""),"Espeon") -> Espeon | BU10: - | BV10: 7 | BX10: =IFERROR(__xludf.DUMMYFUNCTION("""COMPUTED_VALUE"""),"") | BY10: =IFERROR(__xludf.DUMMYFUNCTION("""COMPUTED_VALUE"""),"Chansey") -> Chansey | BZ10: X | CA10: 6 | CC10: =IFERROR(__xludf.DUMMYFUNCTION("""COMPUTED_VALUE"""),"") | CD10: =IFERROR(__xludf.DUMMYFUNCTION("""COMPUTED_VALUE"""),"Dunsparce") -> Dunsparce | CE10: - | CF10: 5 | CH10: =IFERROR(__xludf.DUMMYFUNCTION("""COMPUTED_VALUE"""),"") | CI10: =IFERROR(__xludf.DUMMYFUNCTION("""COMPUTED_VALUE"""),"Bruxish") -> Bruxish | CJ10: - | CK10: 4 | CM10: =IFERROR(__xludf.DUMMYFUNCTION("""COMPUTED_VALUE"""),"") | CN10: =IFERROR(__xludf.DUMMYFUNCTION("""COMPUTED_VALUE"""),"Basculin") -> Basculin | CO10: - | CP10: 3 | CR10: =IFERROR(__xludf.DUMMYFUNCTION("""COMPUTED_VALUE"""),"") | CS10: =IFERROR(__xludf.DUMMYFUNCTION("""COMPUTED_VALUE"""),"Bastiodon") -> Bastiodon | CT10: - | CU10: 3
D11: Giratina-Origin | U11: =IFERROR(__xludf.DUMMYFUNCTION("""COMPUTED_VALUE"""),"") | V11: =IFERROR(__xludf.DUMMYFUNCTION("""COMPUTED_VALUE"""),"Ursaluna-Bloodmoon") -> Ursaluna-Bloodmoon | W11: X | Z11: =IFERROR(__xludf.DUMMYFUNCTION("""COMPUTED_VALUE"""),"") | AA11: =IFERROR(__xludf.DUMMYFUNCTION("""COMPUTED_VALUE"""),"Iron Bundle") -> Iron Bundle | AB11: - | AE11: =IFERROR(__xludf.DUMMYFUNCTION("""COMPUTED_VALUE"""),"") | AF11: =IFERROR(__xludf.DUMMYFUNCTION("""COMPUTED_VALUE"""),"Landorus-Incarnate") -> Landorus-Incarnate | AG11: X | AJ11: =IFERROR(__xludf.DUMMYFUNCTION("""COMPUTED_VALUE"""),"") | AK11: =IFERROR(__xludf.DUMMYFUNCTION("""COMPUTED_VALUE"""),"Heatran") -> Heatran | AL11: X | AO11: =IFERROR(__xludf.DUMMYFUNCTION("""COMPUTED_VALUE"""),"") | AP11: =IFERROR(__xludf.DUMMYFUNCTION("""COMPUTED_VALUE"""),"Hisuian Arcanine") -> Hisuian Arcanine | AQ11: X | AR11: - | AT11: =IFERROR(__xludf.DUMMYFUNCTION("""COMPUTED_VALUE"""),"") | AU11: =IFERROR(__xludf.DUMMYFUNCTION("""COMPUTED_VALUE"""),"Gardevoir") -> Gardevoir | AV11: - | AW11: 13 | AY11: =IFERROR(__xludf.DUMMYFUNCTION("""COMPUTED_VALUE"""),"") | AZ11: =IFERROR(__xludf.DUMMYFUNCTION("""COMPUTED_VALUE"""),"Enamorus-Therian") -> Enamorus-Therian | BA11: - | BB11: 12 | BD11: =IFERROR(__xludf.DUMMYFUNCTION("""COMPUTED_VALUE"""),"") | BE11: =IFERROR(__xludf.DUMMYFUNCTION("""COMPUTED_VALUE"""),"Diancie") -> Diancie | BF11: - | BG11: 11 | BI11: =IFERROR(__xludf.DUMMYFUNCTION("""COMPUTED_VALUE"""),"") | BJ11: =IFERROR(__xludf.DUMMYFUNCTION("""COMPUTED_VALUE"""),"Crawdaunt") -> Crawdaunt | BK11: - | BL11: 9 | BN11: =IFERROR(__xludf.DUMMYFUNCTION("""COMPUTED_VALUE"""),"") | BO11: =IFERROR(__xludf.DUMMYFUNCTION("""COMPUTED_VALUE"""),"Emboar") -> Emboar | BP11: - | BQ11: 8 | BS11: =IFERROR(__xludf.DUMMYFUNCTION("""COMPUTED_VALUE"""),"") | BT11: =IFERROR(__xludf.DUMMYFUNCTION("""COMPUTED_VALUE"""),"Floatzel") -> Floatzel | BU11: - | BV11: 8 | BX11: =IFERROR(__xludf.DUMMYFUNCTION("""COMPUTED_VALUE"""),"") | BY11: =IFERROR(__xludf.DUMMYFUNCTION("""COMPUTED_VALUE"""),"Cinccino") -> Cinccino | BZ11: X | CA11: 6 | CC11: =IFERROR(__xludf.DUMMYFUNCTION("""COMPUTED_VALUE"""),"") | CD11: =IFERROR(__xludf.DUMMYFUNCTION("""COMPUTED_VALUE"""),"Duraludon") -> Duraludon | CE11: - | CF11: 5 | CH11: =IFERROR(__xludf.DUMMYFUNCTION("""COMPUTED_VALUE"""),"") | CI11: =IFERROR(__xludf.DUMMYFUNCTION("""COMPUTED_VALUE"""),"Clawitzer") -> Clawitzer | CJ11: - | CK11: 4 | CM11: =IFERROR(__xludf.DUMMYFUNCTION("""COMPUTED_VALUE"""),"") | CN11: =IFERROR(__xludf.DUMMYFUNCTION("""COMPUTED_VALUE"""),"Beartic") -> Beartic | CO11: - | CP11: 3 | CR11: =IFERROR(__xludf.DUMMYFUNCTION("""COMPUTED_VALUE"""),"") | CS11: =IFERROR(__xludf.DUMMYFUNCTION("""COMPUTED_VALUE"""),"Bayleef") -> Bayleef | CT11: - | CU11: 1
D12: Groudon | U12: =IFERROR(__xludf.DUMMYFUNCTION("""COMPUTED_VALUE"""),"") | V12: =IFERROR(__xludf.DUMMYFUNCTION("""COMPUTED_VALUE"""),"Urshifu-Single-Strike") -> Urshifu-Single-Strike | W12: X | Z12: =IFERROR(__xludf.DUMMYFUNCTION("""COMPUTED_VALUE"""),"") | AA12: =IFERROR(__xludf.DUMMYFUNCTION("""COMPUTED_VALUE"""),"Iron Hands") -> Iron Hands | AB12: X | AE12: =IFERROR(__xludf.DUMMYFUNCTION("""COMPUTED_VALUE"""),"") | AF12: =IFERROR(__xludf.DUMMYFUNCTION("""COMPUTED_VALUE"""),"Landorus-Therian") -> Landorus-Therian | AG12: - | AJ12: =IFERROR(__xludf.DUMMYFUNCTION("""COMPUTED_VALUE"""),"") | AK12: =IFERROR(__xludf.DUMMYFUNCTION("""COMPUTED_VALUE"""),"Infernape") -> Infernape | AL12: - | AO12: =IFERROR(__xludf.DUMMYFUNCTION("""COMPUTED_VALUE"""),"") | AP12: =IFERROR(__xludf.DUMMYFUNCTION("""COMPUTED_VALUE"""),"Hisuian Goodra") -> Hisuian Goodra | AQ12: - | AT12: =IFERROR(__xludf.DUMMYFUNCTION("""COMPUTED_VALUE"""),"") | AU12: =IFERROR(__xludf.DUMMYFUNCTION("""COMPUTED_VALUE"""),"Gothitelle") -> Gothitelle | AV12: - | AW12: 14 | AY12: =IFERROR(__xludf.DUMMYFUNCTION("""COMPUTED_VALUE"""),"") | AZ12: =IFERROR(__xludf.DUMMYFUNCTION("""COMPUTED_VALUE"""),"Fezandipiti") -> Fezandipiti | BA12: - | BB12: 11 | BD12: =IFERROR(__xludf.DUMMYFUNCTION("""COMPUTED_VALUE"""),"") | BE12: =IFERROR(__xludf.DUMMYFUNCTION("""COMPUTED_VALUE"""),"Dondozo") -> Dondozo | BF12: - | BG12: 10 | BI12: =IFERROR(__xludf.DUMMYFUNCTION("""COMPUTED_VALUE"""),"") | BJ12: =IFERROR(__xludf.DUMMYFUNCTION("""COMPUTED_VALUE"""),"Delphox") -> Delphox | BK12: - | BL12: 9 | BN12: =IFERROR(__xludf.DUMMYFUNCTION("""COMPUTED_VALUE"""),"") | BO12: =IFERROR(__xludf.DUMMYFUNCTION("""COMPUTED_VALUE"""),"Farigiraf") -> Farigiraf | BP12: - | BQ12: 8 | BS12: =IFERROR(__xludf.DUMMYFUNCTION("""COMPUTED_VALUE"""),"") | BT12: =IFERROR(__xludf.DUMMYFUNCTION("""COMPUTED_VALUE"""),"Flygon") -> Flygon | BU12: - | BV12: 8 | BX12: =IFERROR(__xludf.DUMMYFUNCTION("""COMPUTED_VALUE"""),"") | BY12: =IFERROR(__xludf.DUMMYFUNCTION("""COMPUTED_VALUE"""),"Drednaw") -> Drednaw | BZ12: - | CA12: 7 | CC12: =IFERROR(__xludf.DUMMYFUNCTION("""COMPUTED_VALUE"""),"") | CD12: =IFERROR(__xludf.DUMMYFUNCTION("""COMPUTED_VALUE"""),"Electivire") -> Electivire | CE12: - | CF12: 5 | CH12: =IFERROR(__xludf.DUMMYFUNCTION("""COMPUTED_VALUE"""),"") | CI12: =IFERROR(__xludf.DUMMYFUNCTION("""COMPUTED_VALUE"""),"Clefairy") -> Clefairy | CJ12: - | CK12: 4 | CM12: =IFERROR(__xludf.DUMMYFUNCTION("""COMPUTED_VALUE"""),"") | CN12: =IFERROR(__xludf.DUMMYFUNCTION("""COMPUTED_VALUE"""),"Bellossom") -> Bellossom | CO12: - | CP12: 3 | CR12: =IFERROR(__xludf.DUMMYFUNCTION("""COMPUTED_VALUE"""),"") | CS12: =IFERROR(__xludf.DUMMYFUNCTION("""COMPUTED_VALUE"""),"Brionne") -> Brionne | CT12: - | CU12: 1
D13: Groudon-Primal | Z13: =IFERROR(__xludf.DUMMYFUNCTION("""COMPUTED_VALUE"""),"") | AA13: =IFERROR(__xludf.DUMMYFUNCTION("""COMPUTED_VALUE"""),"Iron Treads") -> Iron Treads | AB13: - | AE13: =IFERROR(__xludf.DUMMYFUNCTION("""COMPUTED_VALUE"""),"") | AF13: =IFERROR(__xludf.DUMMYFUNCTION("""COMPUTED_VALUE"""),"Mew") -> Mew | AG13: - | AJ13: =IFERROR(__xludf.DUMMYFUNCTION("""COMPUTED_VALUE"""),"") | AK13: =IFERROR(__xludf.DUMMYFUNCTION("""COMPUTED_VALUE"""),"Keldeo") -> Keldeo | AL13: X | AO13: =IFERROR(__xludf.DUMMYFUNCTION("""COMPUTED_VALUE"""),"") | AP13: =IFERROR(__xludf.DUMMYFUNCTION("""COMPUTED_VALUE"""),"Hisuian Lilligant") -> Hisuian Lilligant | AQ13: - | AT13: =IFERROR(__xludf.DUMMYFUNCTION("""COMPUTED_VALUE"""),"") | AU13: =IFERROR(__xludf.DUMMYFUNCTION("""COMPUTED_VALUE"""),"Hatterene") -> Hatterene | AV13: - | AW13: 13 | AY13: =IFERROR(__xludf.DUMMYFUNCTION("""COMPUTED_VALUE"""),"") | AZ13: =IFERROR(__xludf.DUMMYFUNCTION("""COMPUTED_VALUE"""),"Hippowdon") -> Hippowdon | BA13: - | BB13: 11 | BD13: =IFERROR(__xludf.DUMMYFUNCTION("""COMPUTED_VALUE"""),"") | BE13: =IFERROR(__xludf.DUMMYFUNCTION("""COMPUTED_VALUE"""),"Dragalge") -> Dragalge | BF13: X | BG13: 10 | BI13: =IFERROR(__xludf.DUMMYFUNCTION("""COMPUTED_VALUE"""),"") | BJ13: =IFERROR(__xludf.DUMMYFUNCTION("""COMPUTED_VALUE"""),"Dudunsparce") -> Dudunsparce | BK13: - | BL13: 10 | BN13: =IFERROR(__xludf.DUMMYFUNCTION("""COMPUTED_VALUE"""),"") | BO13: =IFERROR(__xludf.DUMMYFUNCTION("""COMPUTED_VALUE"""),"Feraligatr") -> Feraligatr | BP13: - | BQ13: 8 | BS13: =IFERROR(__xludf.DUMMYFUNCTION("""COMPUTED_VALUE"""),"") | BT13: =IFERROR(__xludf.DUMMYFUNCTION("""COMPUTED_VALUE"""),"Froslass") -> Froslass | BU13: X | BV13: 7 | BX13: =IFERROR(__xludf.DUMMYFUNCTION("""COMPUTED_VALUE"""),"") | BY13: =IFERROR(__xludf.DUMMYFUNCTION("""COMPUTED_VALUE"""),"Galarian Articuno") -> Galarian Articuno | BZ13: - | CA13: 7 | CC13: =IFERROR(__xludf.DUMMYFUNCTION("""COMPUTED_VALUE"""),"") | CD13: =IFERROR(__xludf.DUMMYFUNCTION("""COMPUTED_VALUE"""),"Granbull") -> Granbull | CE13: - | CF13: 5 | CH13: =IFERROR(__xludf.DUMMYFUNCTION("""COMPUTED_VALUE"""),"") | CI13: =IFERROR(__xludf.DUMMYFUNCTION("""COMPUTED_VALUE"""),"Dachsbun") -> Dachsbun | CJ13: - | CK13: 4 | CM13: =IFERROR(__xludf.DUMMYFUNCTION("""COMPUTED_VALUE"""),"") | CN13: =IFERROR(__xludf.DUMMYFUNCTION("""COMPUTED_VALUE"""),"Camerupt") -> Camerupt | CO13: - | CP13: 3 | CR13: =IFERROR(__xludf.DUMMYFUNCTION("""COMPUTED_VALUE"""),"") | CS13: =IFERROR(__xludf.DUMMYFUNCTION("""COMPUTED_VALUE"""),"Cacnea") -> Cacnea | CT13: - | CU13: 1
D14: Ho-Oh | Z14: =IFERROR(__xludf.DUMMYFUNCTION("""COMPUTED_VALUE"""),"") | AA14: =IFERROR(__xludf.DUMMYFUNCTION("""COMPUTED_VALUE"""),"Kyurem-Black") -> Kyurem-Black | AB14: X | AE14: =IFERROR(__xludf.DUMMYFUNCTION("""COMPUTED_VALUE"""),"") | AF14: =IFERROR(__xludf.DUMMYFUNCTION("""COMPUTED_VALUE"""),"Ogerpon") -> Ogerpon | AG14: - | AJ14: =IFERROR(__xludf.DUMMYFUNCTION("""COMPUTED_VALUE"""),"") | AK14: =IFERROR(__xludf.DUMMYFUNCTION("""COMPUTED_VALUE"""),"Kommo-o") -> Kommo-o | AL14: - | AO14: =IFERROR(__xludf.DUMMYFUNCTION("""COMPUTED_VALUE"""),"") | AP14: =IFERROR(__xludf.DUMMYFUNCTION("""COMPUTED_VALUE"""),"Hisuian Zoroark") -> Hisuian Zoroark | AQ14: X | AT14: =IFERROR(__xludf.DUMMYFUNCTION("""COMPUTED_VALUE"""),"") | AU14: =IFERROR(__xludf.DUMMYFUNCTION("""COMPUTED_VALUE"""),"Hawlucha") -> Hawlucha | AV14: - | AW14: 12 | AY14: =IFERROR(__xludf.DUMMYFUNCTION("""COMPUTED_VALUE"""),"") | AZ14: =IFERROR(__xludf.DUMMYFUNCTION("""COMPUTED_VALUE"""),"Kleavor") -> Kleavor | BA14: X | BB14: 11 | BD14: =IFERROR(__xludf.DUMMYFUNCTION("""COMPUTED_VALUE"""),"") | BE14: =IFERROR(__xludf.DUMMYFUNCTION("""COMPUTED_VALUE"""),"Entei") -> Entei | BF14: - | BG14: 11 | BI14: =IFERROR(__xludf.DUMMYFUNCTION("""COMPUTED_VALUE"""),"") | BJ14: =IFERROR(__xludf.DUMMYFUNCTION("""COMPUTED_VALUE"""),"Dugtrio") -> Dugtrio | BK14: - | BL14: 10 | BN14: =IFERROR(__xludf.DUMMYFUNCTION("""COMPUTED_VALUE"""),"") | BO14: =IFERROR(__xludf.DUMMYFUNCTION("""COMPUTED_VALUE"""),"Flamigo") -> Flamigo | BP14: - | BQ14: 8 | BS14: =IFERROR(__xludf.DUMMYFUNCTION("""COMPUTED_VALUE"""),"") | BT14: =IFERROR(__xludf.DUMMYFUNCTION("""COMPUTED_VALUE"""),"Galvantula") -> Galvantula | BU14: - | BV14: 7 | BX14: =IFERROR(__xludf.DUMMYFUNCTION("""COMPUTED_VALUE"""),"") | BY14: =IFERROR(__xludf.DUMMYFUNCTION("""COMPUTED_VALUE"""),"Golurk") -> Golurk | BZ14: - | CA14: 6 | CC14: =IFERROR(__xludf.DUMMYFUNCTION("""COMPUTED_VALUE"""),"") | CD14: =IFERROR(__xludf.DUMMYFUNCTION("""COMPUTED_VALUE"""),"Hitmonchan") -> Hitmonchan | CE14: - | CF14: 5 | CH14: =IFERROR(__xludf.DUMMYFUNCTION("""COMPUTED_VALUE"""),"") | CI14: =IFERROR(__xludf.DUMMYFUNCTION("""COMPUTED_VALUE"""),"Ditto") -> Ditto | CJ14: - | CK14: 4 | CM14: =IFERROR(__xludf.DUMMYFUNCTION("""COMPUTED_VALUE"""),"") | CN14: =IFERROR(__xludf.DUMMYFUNCTION("""COMPUTED_VALUE"""),"Carbink") -> Carbink | CO14: - | CP14: 3 | CR14: =IFERROR(__xludf.DUMMYFUNCTION("""COMPUTED_VALUE"""),"") | CS14: =IFERROR(__xludf.DUMMYFUNCTION("""COMPUTED_VALUE"""),"Cacturne") -> Cacturne | CT14: - | CU14: 1
D15: Kyogre | Z15: =IFERROR(__xludf.DUMMYFUNCTION("""COMPUTED_VALUE"""),"") | AA15: =IFERROR(__xludf.DUMMYFUNCTION("""COMPUTED_VALUE"""),"Manaphy") -> Manaphy | AB15: - | AE15: =IFERROR(__xludf.DUMMYFUNCTION("""COMPUTED_VALUE"""),"") | AF15: =IFERROR(__xludf.DUMMYFUNCTION("""COMPUTED_VALUE"""),"Ogerpon-Cornerstone") -> Ogerpon-Cornerstone | AG15: - | AJ15: =IFERROR(__xludf.DUMMYFUNCTION("""COMPUTED_VALUE"""),"") | AK15: =IFERROR(__xludf.DUMMYFUNCTION("""COMPUTED_VALUE"""),"Latias") -> Latias | AL15: X | AO15: =IFERROR(__xludf.DUMMYFUNCTION("""COMPUTED_VALUE"""),"") | AP15: =IFERROR(__xludf.DUMMYFUNCTION("""COMPUTED_VALUE"""),"Hydrapple") -> Hydrapple | AQ15: - | AT15: =IFERROR(__xludf.DUMMYFUNCTION("""COMPUTED_VALUE"""),"") | AU15: =IFERROR(__xludf.DUMMYFUNCTION("""COMPUTED_VALUE"""),"Haxorus") -> Haxorus | AV15: - | AW15: 13 | AY15: =IFERROR(__xludf.DUMMYFUNCTION("""COMPUTED_VALUE"""),"") | AZ15: =IFERROR(__xludf.DUMMYFUNCTION("""COMPUTED_VALUE"""),"Munkidori") -> Munkidori | BA15: - | BB15: 12 | BD15: =IFERROR(__xludf.DUMMYFUNCTION("""COMPUTED_VALUE"""),"") | BE15: =IFERROR(__xludf.DUMMYFUNCTION("""COMPUTED_VALUE"""),"Espathra") -> Espathra | BF15: - | BG15: 13 | BI15: =IFERROR(__xludf.DUMMYFUNCTION("""COMPUTED_VALUE"""),"") | BJ15: =IFERROR(__xludf.DUMMYFUNCTION("""COMPUTED_VALUE"""),"Galarian Weezing") -> Galarian Weezing | BK15: - | BL15: 9 | BN15: =IFERROR(__xludf.DUMMYFUNCTION("""COMPUTED_VALUE"""),"") | BO15: =IFERROR(__xludf.DUMMYFUNCTION("""COMPUTED_VALUE"""),"Forretress") -> Forretress | BP15: - | BQ15: 8 | BS15: =IFERROR(__xludf.DUMMYFUNCTION("""COMPUTED_VALUE"""),"") | BT15: =IFERROR(__xludf.DUMMYFUNCTION("""COMPUTED_VALUE"""),"Grafaiai") -> Grafaiai | BU15: - | BV15: 7 | BX15: =IFERROR(__xludf.DUMMYFUNCTION("""COMPUTED_VALUE"""),"") | BY15: =IFERROR(__xludf.DUMMYFUNCTION("""COMPUTED_VALUE"""),"Gothorita") -> Gothorita | BZ15: - | CA15: 7 | CC15: =IFERROR(__xludf.DUMMYFUNCTION("""COMPUTED_VALUE"""),"") | CD15: =IFERROR(__xludf.DUMMYFUNCTION("""COMPUTED_VALUE"""),"Hitmontop") -> Hitmontop | CE15: - | CF15: 5 | CH15: =IFERROR(__xludf.DUMMYFUNCTION("""COMPUTED_VALUE"""),"") | CI15: =IFERROR(__xludf.DUMMYFUNCTION("""COMPUTED_VALUE"""),"Dusclops") -> Dusclops | CJ15: X | CK15: 4 | CM15: =IFERROR(__xludf.DUMMYFUNCTION("""COMPUTED_VALUE"""),"") | CN15: =IFERROR(__xludf.DUMMYFUNCTION("""COMPUTED_VALUE"""),"Crabominable") -> Crabominable | CO15: - | CP15: 3 | CR15: =IFERROR(__xludf.DUMMYFUNCTION("""COMPUTED_VALUE"""),"") | CS15: =IFERROR(__xludf.DUMMYFUNCTION("""COMPUTED_VALUE"""),"Calyrex") -> Calyrex | CT15: - | CU15: 2
D16: Kyogre-Primal | Z16: =IFERROR(__xludf.DUMMYFUNCTION("""COMPUTED_VALUE"""),"") | AA16: =IFERROR(__xludf.DUMMYFUNCTION("""COMPUTED_VALUE"""),"Necrozma") -> Necrozma | AB16: - | AE16: =IFERROR(__xludf.DUMMYFUNCTION("""COMPUTED_VALUE"""),"") | AF16: =IFERROR(__xludf.DUMMYFUNCTION("""COMPUTED_VALUE"""),"Roaring Moon") -> Roaring Moon | AG16: - | AJ16: =IFERROR(__xludf.DUMMYFUNCTION("""COMPUTED_VALUE"""),"") | AK16: =IFERROR(__xludf.DUMMYFUNCTION("""COMPUTED_VALUE"""),"Metagross") -> Metagross | AL16: - | AO16: =IFERROR(__xludf.DUMMYFUNCTION("""COMPUTED_VALUE"""),"") | AP16: =IFERROR(__xludf.DUMMYFUNCTION("""COMPUTED_VALUE"""),"Hydreigon") -> Hydreigon | AQ16: - | AT16: =IFERROR(__xludf.DUMMYFUNCTION("""COMPUTED_VALUE"""),"") | AU16: =IFERROR(__xludf.DUMMYFUNCTION("""COMPUTED_VALUE"""),"Hoopa-Unbound") -> Hoopa-Unbound | AV16: X | AW16: 13 | AY16: =IFERROR(__xludf.DUMMYFUNCTION("""COMPUTED_VALUE"""),"") | AZ16: =IFERROR(__xludf.DUMMYFUNCTION("""COMPUTED_VALUE"""),"Noivern") -> Noivern | BA16: X | BB16: 11 | BD16: =IFERROR(__xludf.DUMMYFUNCTION("""COMPUTED_VALUE"""),"") | BE16: =IFERROR(__xludf.DUMMYFUNCTION("""COMPUTED_VALUE"""),"Florges") -> Florges | BF16: - | BG16: 10 | BI16: =IFERROR(__xludf.DUMMYFUNCTION("""COMPUTED_VALUE"""),"") | BJ16: =IFERROR(__xludf.DUMMYFUNCTION("""COMPUTED_VALUE"""),"Garganacl") -> Garganacl | BK16: - | BL16: 11 | BN16: =IFERROR(__xludf.DUMMYFUNCTION("""COMPUTED_VALUE"""),"") | BO16: =IFERROR(__xludf.DUMMYFUNCTION("""COMPUTED_VALUE"""),"Gastrodon") -> Gastrodon | BP16: - | BQ16: 8 | BS16: =IFERROR(__xludf.DUMMYFUNCTION("""COMPUTED_VALUE"""),"") | BT16: =IFERROR(__xludf.DUMMYFUNCTION("""COMPUTED_VALUE"""),"Hisuian Typhlosion") -> Hisuian Typhlosion | BU16: - | BV16: 7 | BX16: =IFERROR(__xludf.DUMMYFUNCTION("""COMPUTED_VALUE"""),"") | BY16: =IFERROR(__xludf.DUMMYFUNCTION("""COMPUTED_VALUE"""),"Hisuian Decidueye") -> Hisuian Decidueye | BZ16: - | CA16: 6 | CC16: =IFERROR(__xludf.DUMMYFUNCTION("""COMPUTED_VALUE"""),"") | CD16: =IFERROR(__xludf.DUMMYFUNCTION("""COMPUTED_VALUE"""),"Lanturn") -> Lanturn | CE16: - | CF16: 5 | CH16: =IFERROR(__xludf.DUMMYFUNCTION("""COMPUTED_VALUE"""),"") | CI16: =IFERROR(__xludf.DUMMYFUNCTION("""COMPUTED_VALUE"""),"Dusknoir") -> Dusknoir | CJ16: - | CK16: 4 | CM16: =IFERROR(__xludf.DUMMYFUNCTION("""COMPUTED_VALUE"""),"") | CN16: =IFERROR(__xludf.DUMMYFUNCTION("""COMPUTED_VALUE"""),"Cramorant") -> Cramorant | CO16: - | CP16: 3 | CR16: =IFERROR(__xludf.DUMMYFUNCTION("""COMPUTED_VALUE"""),"") | CS16: =IFERROR(__xludf.DUMMYFUNCTION("""COMPUTED_VALUE"""),"Carkol") -> Carkol | CT16: - | CU16: 2
D17: Kyurem-White | Z17: =IFERROR(__xludf.DUMMYFUNCTION("""COMPUTED_VALUE"""),"") | AA17: =IFERROR(__xludf.DUMMYFUNCTION("""COMPUTED_VALUE"""),"Ogerpon-Wellspring") -> Ogerpon-Wellspring | AB17: X | AE17: =IFERROR(__xludf.DUMMYFUNCTION("""COMPUTED_VALUE"""),"") | AF17: =IFERROR(__xludf.DUMMYFUNCTION("""COMPUTED_VALUE"""),"Rotom-Wash") -> Rotom-Wash | AG17: X | AJ17: =IFERROR(__xludf.DUMMYFUNCTION("""COMPUTED_VALUE"""),"") | AK17: =IFERROR(__xludf.DUMMYFUNCTION("""COMPUTED_VALUE"""),"Ogerpon-Hearthflame") -> Ogerpon-Hearthflame | AL17: X | AO17: =IFERROR(__xludf.DUMMYFUNCTION("""COMPUTED_VALUE"""),"") | AP17: =IFERROR(__xludf.DUMMYFUNCTION("""COMPUTED_VALUE"""),"Iron Jugulis") -> Iron Jugulis | AQ17: X | AT17: =IFERROR(__xludf.DUMMYFUNCTION("""COMPUTED_VALUE"""),"") | AU17: =IFERROR(__xludf.DUMMYFUNCTION("""COMPUTED_VALUE"""),"Iron Crown") -> Iron Crown | AV17: - | AW17: 14 | AY17: =IFERROR(__xludf.DUMMYFUNCTION("""COMPUTED_VALUE"""),"") | AZ17: =IFERROR(__xludf.DUMMYFUNCTION("""COMPUTED_VALUE"""),"Okidogi") -> Okidogi | BA17: - | BB17: 13 | BD17: =IFERROR(__xludf.DUMMYFUNCTION("""COMPUTED_VALUE"""),"") | BE17: =IFERROR(__xludf.DUMMYFUNCTION("""COMPUTED_VALUE"""),"Galarian Slowbro") -> Galarian Slowbro | BF17: - | BG17: 10 | BI17: =IFERROR(__xludf.DUMMYFUNCTION("""COMPUTED_VALUE"""),"") | BJ17: =IFERROR(__xludf.DUMMYFUNCTION("""COMPUTED_VALUE"""),"Goodra") -> Goodra | BK17: - | BL17: 9 | BN17: =IFERROR(__xludf.DUMMYFUNCTION("""COMPUTED_VALUE"""),"") | BO17: =IFERROR(__xludf.DUMMYFUNCTION("""COMPUTED_VALUE"""),"Glastrier") -> Glastrier | BP17: - | BQ17: 9 | BS17: =IFERROR(__xludf.DUMMYFUNCTION("""COMPUTED_VALUE"""),"") | BT17: =IFERROR(__xludf.DUMMYFUNCTION("""COMPUTED_VALUE"""),"Hitmonlee") -> Hitmonlee | BU17: - | BV17: 7 | BX17: =IFERROR(__xludf.DUMMYFUNCTION("""COMPUTED_VALUE"""),"") | BY17: =IFERROR(__xludf.DUMMYFUNCTION("""COMPUTED_VALUE"""),"Hoopa") -> Hoopa | BZ17: - | CA17: 6 | CC17: =IFERROR(__xludf.DUMMYFUNCTION("""COMPUTED_VALUE"""),"") | CD17: =IFERROR(__xludf.DUMMYFUNCTION("""COMPUTED_VALUE"""),"Mabosstiff") -> Mabosstiff | CE17: - | CF17: 5 | CH17: =IFERROR(__xludf.DUMMYFUNCTION("""COMPUTED_VALUE"""),"") | CI17: =IFERROR(__xludf.DUMMYFUNCTION("""COMPUTED_VALUE"""),"Electrode") -> Electrode | CJ17: - | CK17: 5 | CM17: =IFERROR(__xludf.DUMMYFUNCTION("""COMPUTED_VALUE"""),"") | CN17: =IFERROR(__xludf.DUMMYFUNCTION("""COMPUTED_VALUE"""),"Crocalor") -> Crocalor | CO17: - | CP17: 3 | CR17: =IFERROR(__xludf.DUMMYFUNCTION("""COMPUTED_VALUE"""),"") | CS17: =IFERROR(__xludf.DUMMYFUNCTION("""COMPUTED_VALUE"""),"Charjabug") -> Charjabug | CT17: - | CU17: 1
D18: Lugia | Z18: =IFERROR(__xludf.DUMMYFUNCTION("""COMPUTED_VALUE"""),"") | AA18: =IFERROR(__xludf.DUMMYFUNCTION("""COMPUTED_VALUE"""),"Quaquaval") -> Quaquaval | AB18: - | AE18: =IFERROR(__xludf.DUMMYFUNCTION("""COMPUTED_VALUE"""),"") | AF18: =IFERROR(__xludf.DUMMYFUNCTION("""COMPUTED_VALUE"""),"Urshifu-Rapid-Strike") -> Urshifu-Rapid-Strike | AG18: - | AJ18: =IFERROR(__xludf.DUMMYFUNCTION("""COMPUTED_VALUE"""),"") | AK18: =IFERROR(__xludf.DUMMYFUNCTION("""COMPUTED_VALUE"""),"Salamence") -> Salamence | AL18: - | AO18: =IFERROR(__xludf.DUMMYFUNCTION("""COMPUTED_VALUE"""),"") | AP18: =IFERROR(__xludf.DUMMYFUNCTION("""COMPUTED_VALUE"""),"Krookodile") -> Krookodile | AQ18: X | AT18: =IFERROR(__xludf.DUMMYFUNCTION("""COMPUTED_VALUE"""),"") | AU18: =IFERROR(__xludf.DUMMYFUNCTION("""COMPUTED_VALUE"""),"Klefki") -> Klefki | AV18: - | AW18: 12 | AY18: =IFERROR(__xludf.DUMMYFUNCTION("""COMPUTED_VALUE"""),"") | AZ18: =IFERROR(__xludf.DUMMYFUNCTION("""COMPUTED_VALUE"""),"Overqwil") -> Overqwil | BA18: - | BB18: 11 | BD18: =IFERROR(__xludf.DUMMYFUNCTION("""COMPUTED_VALUE"""),"") | BE18: =IFERROR(__xludf.DUMMYFUNCTION("""COMPUTED_VALUE"""),"Gallade") -> Gallade | BF18: - | BG18: 11 | BI18: =IFERROR(__xludf.DUMMYFUNCTION("""COMPUTED_VALUE"""),"") | BJ18: =IFERROR(__xludf.DUMMYFUNCTION("""COMPUTED_VALUE"""),"Gyarados") -> Gyarados | BK18: - | BL18: 11 | BN18: =IFERROR(__xludf.DUMMYFUNCTION("""COMPUTED_VALUE"""),"") | BO18: =IFERROR(__xludf.DUMMYFUNCTION("""COMPUTED_VALUE"""),"Hariyama") -> Hariyama | BP18: - | BQ18: 9 | BS18: =IFERROR(__xludf.DUMMYFUNCTION("""COMPUTED_VALUE"""),"") | BT18: =IFERROR(__xludf.DUMMYFUNCTION("""COMPUTED_VALUE"""),"Houndstone") -> Houndstone | BU18: - | BV18: 7 | BX18: =IFERROR(__xludf.DUMMYFUNCTION("""COMPUTED_VALUE"""),"") | BY18: =IFERROR(__xludf.DUMMYFUNCTION("""COMPUTED_VALUE"""),"Iron Thorns") -> Iron Thorns | BZ18: - | CA18: 7 | CC18: =IFERROR(__xludf.DUMMYFUNCTION("""COMPUTED_VALUE"""),"") | CD18: =IFERROR(__xludf.DUMMYFUNCTION("""COMPUTED_VALUE"""),"Poliwrath") -> Poliwrath | CE18: - | CF18: 5 | CH18: =IFERROR(__xludf.DUMMYFUNCTION("""COMPUTED_VALUE"""),"") | CI18: =IFERROR(__xludf.DUMMYFUNCTION("""COMPUTED_VALUE"""),"Flapple") -> Flapple | CJ18: - | CK18: 4 | CM18: =IFERROR(__xludf.DUMMYFUNCTION("""COMPUTED_VALUE"""),"") | CN18: =IFERROR(__xludf.DUMMYFUNCTION("""COMPUTED_VALUE"""),"Dewgong") -> Dewgong | CO18: - | CP18: 3 | CR18: =IFERROR(__xludf.DUMMYFUNCTION("""COMPUTED_VALUE"""),"") | CS18: =IFERROR(__xludf.DUMMYFUNCTION("""COMPUTED_VALUE"""),"Chimecho") -> Chimecho | CT18: - | CU18: 2
D19: Lunala | Z19: =IFERROR(__xludf.DUMMYFUNCTION("""COMPUTED_VALUE"""),"") | AA19: =IFERROR(__xludf.DUMMYFUNCTION("""COMPUTED_VALUE"""),"Ting-Lu") -> Ting-Lu | AB19: - | AE19: =IFERROR(__xludf.DUMMYFUNCTION("""COMPUTED_VALUE"""),"") | AF19: =IFERROR(__xludf.DUMMYFUNCTION("""COMPUTED_VALUE"""),"Walking Wake") -> Walking Wake | AG19: X | AJ19: =IFERROR(__xludf.DUMMYFUNCTION("""COMPUTED_VALUE"""),"") | AK19: =IFERROR(__xludf.DUMMYFUNCTION("""COMPUTED_VALUE"""),"Scizor") -> Scizor | AL19: X | AO19: =IFERROR(__xludf.DUMMYFUNCTION("""COMPUTED_VALUE"""),"") | AP19: =IFERROR(__xludf.DUMMYFUNCTION("""COMPUTED_VALUE"""),"Lycanroc-Dusk") -> Lycanroc-Dusk | AQ19: - | AT19: =IFERROR(__xludf.DUMMYFUNCTION("""COMPUTED_VALUE"""),"") | AU19: =IFERROR(__xludf.DUMMYFUNCTION("""COMPUTED_VALUE"""),"Mamoswine") -> Mamoswine | AV19: X | AW19: 12 | AY19: =IFERROR(__xludf.DUMMYFUNCTION("""COMPUTED_VALUE"""),"") | AZ19: =IFERROR(__xludf.DUMMYFUNCTION("""COMPUTED_VALUE"""),"Paldean Tauros-Water") -> Paldean Tauros-Water | BA19: - | BB19: 11 | BD19: =IFERROR(__xludf.DUMMYFUNCTION("""COMPUTED_VALUE"""),"") | BE19: =IFERROR(__xludf.DUMMYFUNCTION("""COMPUTED_VALUE"""),"Heracross") -> Heracross | BF19: - | BG19: 10 | BI19: =IFERROR(__xludf.DUMMYFUNCTION("""COMPUTED_VALUE"""),"") | BJ19: =IFERROR(__xludf.DUMMYFUNCTION("""COMPUTED_VALUE"""),"Hisuian Braviary") -> Hisuian Braviary | BK19: - | BL19: 10 | BN19: =IFERROR(__xludf.DUMMYFUNCTION("""COMPUTED_VALUE"""),"") | BO19: =IFERROR(__xludf.DUMMYFUNCTION("""COMPUTED_VALUE"""),"Hisuian Qwilfish") -> Hisuian Qwilfish | BP19: - | BQ19: 8 | BS19: =IFERROR(__xludf.DUMMYFUNCTION("""COMPUTED_VALUE"""),"") | BT19: =IFERROR(__xludf.DUMMYFUNCTION("""COMPUTED_VALUE"""),"Indeedee-Female") -> Indeedee-Female | BU19: - | BV19: 7 | BX19: =IFERROR(__xludf.DUMMYFUNCTION("""COMPUTED_VALUE"""),"") | BY19: =IFERROR(__xludf.DUMMYFUNCTION("""COMPUTED_VALUE"""),"Jolteon") -> Jolteon | BZ19: - | CA19: 9 | CC19: =IFERROR(__xludf.DUMMYFUNCTION("""COMPUTED_VALUE"""),"") | CD19: =IFERROR(__xludf.DUMMYFUNCTION("""COMPUTED_VALUE"""),"Quilladin") -> Quilladin | CE19: - | CF19: 5 | CH19: =IFERROR(__xludf.DUMMYFUNCTION("""COMPUTED_VALUE"""),"") | CI19: =IFERROR(__xludf.DUMMYFUNCTION("""COMPUTED_VALUE"""),"Frosmoth") -> Frosmoth | CJ19: - | CK19: 5 | CM19: =IFERROR(__xludf.DUMMYFUNCTION("""COMPUTED_VALUE"""),"") | CN19: =IFERROR(__xludf.DUMMYFUNCTION("""COMPUTED_VALUE"""),"Dodrio") -> Dodrio | CO19: - | CP19: 3 | CR19: =IFERROR(__xludf.DUMMYFUNCTION("""COMPUTED_VALUE"""),"") | CS19: =IFERROR(__xludf.DUMMYFUNCTION("""COMPUTED_VALUE"""),"Cosmoem") -> Cosmoem | CT19: - | CU19: 1
D20: Magearna | Z20: =IFERROR(__xludf.DUMMYFUNCTION("""COMPUTED_VALUE"""),"") | AA20: =IFERROR(__xludf.DUMMYFUNCTION("""COMPUTED_VALUE"""),"Weavile") -> Weavile | AB20: - | AJ20: =IFERROR(__xludf.DUMMYFUNCTION("""COMPUTED_VALUE"""),"") | AK20: =IFERROR(__xludf.DUMMYFUNCTION("""COMPUTED_VALUE"""),"Scream Tail") -> Scream Tail | AL20: - | AO20: =IFERROR(__xludf.DUMMYFUNCTION("""COMPUTED_VALUE"""),"") | AP20: =IFERROR(__xludf.DUMMYFUNCTION("""COMPUTED_VALUE"""),"Mienshao") -> Mienshao | AQ20: - | AT20: =IFERROR(__xludf.DUMMYFUNCTION("""COMPUTED_VALUE"""),"") | AU20: =IFERROR(__xludf.DUMMYFUNCTION("""COMPUTED_VALUE"""),"Pawmot") -> Pawmot | AV20: - | AW20: 12 | AY20: =IFERROR(__xludf.DUMMYFUNCTION("""COMPUTED_VALUE"""),"") | AZ20: =IFERROR(__xludf.DUMMYFUNCTION("""COMPUTED_VALUE"""),"Rotom-Heat") -> Rotom-Heat | BA20: - | BB20: 11 | BD20: =IFERROR(__xludf.DUMMYFUNCTION("""COMPUTED_VALUE"""),"") | BE20: =IFERROR(__xludf.DUMMYFUNCTION("""COMPUTED_VALUE"""),"Hisuian Electrode") -> Hisuian Electrode | BF20: - | BG20: 11 | BI20: =IFERROR(__xludf.DUMMYFUNCTION("""COMPUTED_VALUE"""),"") | BJ20: =IFERROR(__xludf.DUMMYFUNCTION("""COMPUTED_VALUE"""),"Inteleon") -> Inteleon | BK20: - | BL20: 9 | BN20: =IFERROR(__xludf.DUMMYFUNCTION("""COMPUTED_VALUE"""),"") | BO20: =IFERROR(__xludf.DUMMYFUNCTION("""COMPUTED_VALUE"""),"Incineroar") -> Incineroar | BP20: - | BQ20: 8 | BS20: =IFERROR(__xludf.DUMMYFUNCTION("""COMPUTED_VALUE"""),"") | BT20: =IFERROR(__xludf.DUMMYFUNCTION("""COMPUTED_VALUE"""),"Medicham") -> Medicham | BU20: - | BV20: 7 | BX20: =IFERROR(__xludf.DUMMYFUNCTION("""COMPUTED_VALUE"""),"") | BY20: =IFERROR(__xludf.DUMMYFUNCTION("""COMPUTED_VALUE"""),"Lycanroc-Midday") -> Lycanroc-Midday | BZ20: - | CA20: 7 | CC20: =IFERROR(__xludf.DUMMYFUNCTION("""COMPUTED_VALUE"""),"") | CD20: =IFERROR(__xludf.DUMMYFUNCTION("""COMPUTED_VALUE"""),"Raichu") -> Raichu | CE20: - | CF20: 5 | CH20: =IFERROR(__xludf.DUMMYFUNCTION("""COMPUTED_VALUE"""),"") | CI20: =IFERROR(__xludf.DUMMYFUNCTION("""COMPUTED_VALUE"""),"Greedent") -> Greedent | CJ20: - | CK20: 4 | CM20: =IFERROR(__xludf.DUMMYFUNCTION("""COMPUTED_VALUE"""),"") | CN20: =IFERROR(__xludf.DUMMYFUNCTION("""COMPUTED_VALUE"""),"Duosion") -> Duosion | CO20: - | CP20: 3 | CR20: =IFERROR(__xludf.DUMMYFUNCTION("""COMPUTED_VALUE"""),"") | CS20: =IFERROR(__xludf.DUMMYFUNCTION("""COMPUTED_VALUE"""),"Croconaw") -> Croconaw | CT20: - | CU20: 1
D21: Mewtwo | Z21: =IFERROR(__xludf.DUMMYFUNCTION("""COMPUTED_VALUE"""),"") | AA21: =IFERROR(__xludf.DUMMYFUNCTION("""COMPUTED_VALUE"""),"Zapdos") -> Zapdos | AB21: X | AJ21: =IFERROR(__xludf.DUMMYFUNCTION("""COMPUTED_VALUE"""),"") | AK21: =IFERROR(__xludf.DUMMYFUNCTION("""COMPUTED_VALUE"""),"Skarmory") -> Skarmory | AL21: - | AO21: =IFERROR(__xludf.DUMMYFUNCTION("""COMPUTED_VALUE"""),"") | AP21: =IFERROR(__xludf.DUMMYFUNCTION("""COMPUTED_VALUE"""),"Raging Bolt") -> Raging Bolt | AQ21: X | AT21: =IFERROR(__xludf.DUMMYFUNCTION("""COMPUTED_VALUE"""),"") | AU21: =IFERROR(__xludf.DUMMYFUNCTION("""COMPUTED_VALUE"""),"Primarina") -> Primarina | AV21: - | AW21: 13 | AY21: =IFERROR(__xludf.DUMMYFUNCTION("""COMPUTED_VALUE"""),"") | AZ21: =IFERROR(__xludf.DUMMYFUNCTION("""COMPUTED_VALUE"""),"Slowbro") -> Slowbro | BA21: - | BB21: 11 | BD21: =IFERROR(__xludf.DUMMYFUNCTION("""COMPUTED_VALUE"""),"") | BE21: =IFERROR(__xludf.DUMMYFUNCTION("""COMPUTED_VALUE"""),"Lokix") -> Lokix | BF21: - | BG21: 10 | BI21: =IFERROR(__xludf.DUMMYFUNCTION("""COMPUTED_VALUE"""),"") | BJ21: =IFERROR(__xludf.DUMMYFUNCTION("""COMPUTED_VALUE"""),"Iron Leaves") -> Iron Leaves | BK21: - | BL21: 11 | BN21: =IFERROR(__xludf.DUMMYFUNCTION("""COMPUTED_VALUE"""),"") | BO21: =IFERROR(__xludf.DUMMYFUNCTION("""COMPUTED_VALUE"""),"Kilowattrel") -> Kilowattrel | BP21: - | BQ21: 9 | BS21: =IFERROR(__xludf.DUMMYFUNCTION("""COMPUTED_VALUE"""),"") | BT21: =IFERROR(__xludf.DUMMYFUNCTION("""COMPUTED_VALUE"""),"Paldean Tauros") -> Paldean Tauros | BU21: - | BV21: 7 | BX21: =IFERROR(__xludf.DUMMYFUNCTION("""COMPUTED_VALUE"""),"") | BY21: =IFERROR(__xludf.DUMMYFUNCTION("""COMPUTED_VALUE"""),"Magneton") -> Magneton | BZ21: - | CA21: 6 | CC21: =IFERROR(__xludf.DUMMYFUNCTION("""COMPUTED_VALUE"""),"") | CD21: =IFERROR(__xludf.DUMMYFUNCTION("""COMPUTED_VALUE"""),"Regirock") -> Regirock | CE21: - | CF21: 5 | CH21: =IFERROR(__xludf.DUMMYFUNCTION("""COMPUTED_VALUE"""),"") | CI21: =IFERROR(__xludf.DUMMYFUNCTION("""COMPUTED_VALUE"""),"Gurdurr") -> Gurdurr | CJ21: - | CK21: 4 | CM21: =IFERROR(__xludf.DUMMYFUNCTION("""COMPUTED_VALUE"""),"") | CN21: =IFERROR(__xludf.DUMMYFUNCTION("""COMPUTED_VALUE"""),"Eiscue") -> Eiscue | CO21: - | CP21: 3 | CR21: =IFERROR(__xludf.DUMMYFUNCTION("""COMPUTED_VALUE"""),"") | CS21: =IFERROR(__xludf.DUMMYFUNCTION("""COMPUTED_VALUE"""),"Dedenne") -> Dedenne | CT21: - | CU21: 1
D22: Mewtwo-Mega X | AJ22: =IFERROR(__xludf.DUMMYFUNCTION("""COMPUTED_VALUE"""),"") | AK22: =IFERROR(__xludf.DUMMYFUNCTION("""COMPUTED_VALUE"""),"Slowking") -> Slowking | AL22: - | AO22: =IFERROR(__xludf.DUMMYFUNCTION("""COMPUTED_VALUE"""),"") | AP22: =IFERROR(__xludf.DUMMYFUNCTION("""COMPUTED_VALUE"""),"Raikou") -> Raikou | AQ22: X | AT22: =IFERROR(__xludf.DUMMYFUNCTION("""COMPUTED_VALUE"""),"") | AU22: =IFERROR(__xludf.DUMMYFUNCTION("""COMPUTED_VALUE"""),"Reuniclus") -> Reuniclus | AV22: - | AW22: 13 | AY22: =IFERROR(__xludf.DUMMYFUNCTION("""COMPUTED_VALUE"""),"") | AZ22: =IFERROR(__xludf.DUMMYFUNCTION("""COMPUTED_VALUE"""),"Snorlax") -> Snorlax | BA22: - | BB22: 12 | BD22: =IFERROR(__xludf.DUMMYFUNCTION("""COMPUTED_VALUE"""),"") | BE22: =IFERROR(__xludf.DUMMYFUNCTION("""COMPUTED_VALUE"""),"Mandibuzz") -> Mandibuzz | BF22: - | BG22: 10 | BI22: =IFERROR(__xludf.DUMMYFUNCTION("""COMPUTED_VALUE"""),"") | BJ22: =IFERROR(__xludf.DUMMYFUNCTION("""COMPUTED_VALUE"""),"Milotic") -> Milotic | BK22: - | BL22: 9 | BN22: =IFERROR(__xludf.DUMMYFUNCTION("""COMPUTED_VALUE"""),"") | BO22: =IFERROR(__xludf.DUMMYFUNCTION("""COMPUTED_VALUE"""),"Kingdra") -> Kingdra | BP22: X | BQ22: 8 | BS22: =IFERROR(__xludf.DUMMYFUNCTION("""COMPUTED_VALUE"""),"") | BT22: =IFERROR(__xludf.DUMMYFUNCTION("""COMPUTED_VALUE"""),"Passimian") -> Passimian | BU22: - | BV22: 7 | BX22: =IFERROR(__xludf.DUMMYFUNCTION("""COMPUTED_VALUE"""),"") | BY22: =IFERROR(__xludf.DUMMYFUNCTION("""COMPUTED_VALUE"""),"Maushold") -> Maushold | BZ22: - | CA22: 6 | CC22: =IFERROR(__xludf.DUMMYFUNCTION("""COMPUTED_VALUE"""),"") | CD22: =IFERROR(__xludf.DUMMYFUNCTION("""COMPUTED_VALUE"""),"Rhydon") -> Rhydon | CE22: - | CF22: 5 | CH22: =IFERROR(__xludf.DUMMYFUNCTION("""COMPUTED_VALUE"""),"") | CI22: =IFERROR(__xludf.DUMMYFUNCTION("""COMPUTED_VALUE"""),"Honchkrow") -> Honchkrow | CJ22: - | CK22: 4 | CM22: =IFERROR(__xludf.DUMMYFUNCTION("""COMPUTED_VALUE"""),"") | CN22: =IFERROR(__xludf.DUMMYFUNCTION("""COMPUTED_VALUE"""),"Electabuzz") -> Electabuzz | CO22: - | CP22: 3 | CR22: =IFERROR(__xludf.DUMMYFUNCTION("""COMPUTED_VALUE"""),"") | CS22: =IFERROR(__xludf.DUMMYFUNCTION("""COMPUTED_VALUE"""),"Delibird") -> Delibird | CT22: - | CU22: 1
D23: Mewtwo-Mega Y | AJ23: =IFERROR(__xludf.DUMMYFUNCTION("""COMPUTED_VALUE"""),"") | AK23: =IFERROR(__xludf.DUMMYFUNCTION("""COMPUTED_VALUE"""),"Swampert") -> Swampert | AL23: - | AO23: =IFERROR(__xludf.DUMMYFUNCTION("""COMPUTED_VALUE"""),"") | AP23: =IFERROR(__xludf.DUMMYFUNCTION("""COMPUTED_VALUE"""),"Serperior") -> Serperior | AQ23: - | AT23: =IFERROR(__xludf.DUMMYFUNCTION("""COMPUTED_VALUE"""),"") | AU23: =IFERROR(__xludf.DUMMYFUNCTION("""COMPUTED_VALUE"""),"Rillaboom") -> Rillaboom | AV23: - | AW23: 13 | AY23: =IFERROR(__xludf.DUMMYFUNCTION("""COMPUTED_VALUE"""),"") | AZ23: =IFERROR(__xludf.DUMMYFUNCTION("""COMPUTED_VALUE"""),"Talonflame") -> Talonflame | BA23: - | BB23: 11 | BD23: =IFERROR(__xludf.DUMMYFUNCTION("""COMPUTED_VALUE"""),"") | BE23: =IFERROR(__xludf.DUMMYFUNCTION("""COMPUTED_VALUE"""),"Meloetta") -> Meloetta | BF23: - | BG23: 11 | BI23: =IFERROR(__xludf.DUMMYFUNCTION("""COMPUTED_VALUE"""),"") | BJ23: =IFERROR(__xludf.DUMMYFUNCTION("""COMPUTED_VALUE"""),"Quagsire") -> Quagsire | BK23: - | BL23: 9 | BN23: =IFERROR(__xludf.DUMMYFUNCTION("""COMPUTED_VALUE"""),"") | BO23: =IFERROR(__xludf.DUMMYFUNCTION("""COMPUTED_VALUE"""),"Lucario") -> Lucario | BP23: - | BQ23: 10 | BS23: =IFERROR(__xludf.DUMMYFUNCTION("""COMPUTED_VALUE"""),"") | BT23: =IFERROR(__xludf.DUMMYFUNCTION("""COMPUTED_VALUE"""),"Piloswine") -> Piloswine | BU23: - | BV23: 7 | BX23: =IFERROR(__xludf.DUMMYFUNCTION("""COMPUTED_VALUE"""),"") | BY23: =IFERROR(__xludf.DUMMYFUNCTION("""COMPUTED_VALUE"""),"Muk") -> Muk | BZ23: - | CA23: 6 | CC23: =IFERROR(__xludf.DUMMYFUNCTION("""COMPUTED_VALUE"""),"") | CD23: =IFERROR(__xludf.DUMMYFUNCTION("""COMPUTED_VALUE"""),"Scovillain") -> Scovillain | CE23: - | CF23: 6 | CH23: =IFERROR(__xludf.DUMMYFUNCTION("""COMPUTED_VALUE"""),"") | CI23: =IFERROR(__xludf.DUMMYFUNCTION("""COMPUTED_VALUE"""),"Lapras") -> Lapras | CJ23: - | CK23: 4 | CM23: =IFERROR(__xludf.DUMMYFUNCTION("""COMPUTED_VALUE"""),"") | CN23: =IFERROR(__xludf.DUMMYFUNCTION("""COMPUTED_VALUE"""),"Exeggutor") -> Exeggutor | CO23: - | CP23: 3 | CR23: =IFERROR(__xludf.DUMMYFUNCTION("""COMPUTED_VALUE"""),"") | CS23: =IFERROR(__xludf.DUMMYFUNCTION("""COMPUTED_VALUE"""),"Diglett") -> Diglett | CT23: - | CU23: 1
