Workbook

Sheet Home
C3: Scarlet Violet Pokemon Draft League | E3: =Source!$J$3 | F3: =Source!$J$4 | G3: =Source!$J$5
C4: Year 1 | E4: =Source!$F$3 -> Jackson McLoughlin | F4: =Source!$F$6 -> Ian Heslin | G4: =Source!$F$5 -> Dick Hansen
E5: =Source!$J$6 | F5: =Source!$J$7 | G5: =Source!$J$8
E6: =Source!$F$4 -> Zach VanSickle | F6: =Source!$F$7 -> Ryan Tidey | G6: =Source!$F$8 -> Tyler Gottfredsen

Sheet Rules
E3: WPF Weather Division Rules
C5: League Rules
C6: # 1 | D6: 🟍 The season will be 7 weeks. You will play your divison twice and the other divison once.
C7: # 2 | D7: 🟍 All matches must be played in the "[Gen 9] VGC 2023 Series 2" format.
C8: # 3 | D8: 🟍 Any additional questions may be asked in the Pokemon League Discord. Please @authorzed.
C10: Drafting Rules
C11: # 1 | D11: 🟍 Drafting will be the standard snake style, from 1-6 then again from 6 back to 1.
C12: 2 | D12: 🟍 Coaches have 70 points to draft 9-10 pokemon on their team.
C13: 3 | D13: 🟍 Species clause is in effect: You may not draft 2 pokemon of the same species (Ex: two Rotoms, Aegislash & Doublade, Mega Scizor & Scizor)
C14: 4 | D14: 🟍 There will be a 24 hour grace period that starts immediately after the draft concludes.
C16: Season Rules
C17: # 1 | D17: 🟍 Coaches are allowed 5 FA transactions throughout the season once the grace period has concluded. Coach to coach trades are infinite.
C18: # 2 | D18: 🟍 Coaches are no longer able to use FA transactions after week 7 has concluded. Rosters become frozen before playoffs.
C19: # 3 | D19: 🟍 The top 6 teams at the end of the regular season will progress to playoffs.
C20: # 4 | D20: 🟍 When determining playoff seeding, the following measure will be used: Series Wins>Game Wins>Differential> Head-to-Head>Strength of Schedule.
C22: Battle Rules
C23: # 1 | D23: 🟍 Battles are to be done every other week. Please coordinate with you opponet for the week through text or discord.
C24: # 2 | D24: 🟍 All matches are best of three, with open team sheets.
C25: # 3 | D25: 🟍 All pokemon will be set to level 50.
C26: # 4 | D26: 🟍 Item clause is in effect for all battles. Berserk Gene, non-normal gems, mega stones, and Z-Crystals are banned.
C27: # 5 | D27: 🟍 Battle timer may be turned on by either coach for any reason. That coach is under no obligation to turn off timer unless their opponent disconnects unexpectantly. If this should happen, contact an online mod who will make the timer decision on your behalf.

Sheet Standings
A1: x
C3: Drizzle Standings
C4: 1 | D4: =vlookup(E4,Source!$F$3:$K$18,5,FALSE) | E4: =Data!$AN$5 -> Ian Heslin | F4: =CountIF(G4:K5,"W")&"-"&CountIF(G4:K5,"L") -> 7-0 | G4: =vlookup(E4,Data!$M$5:$X$10,6,FALSE) -> W | H4: =vlookup(E4,Data!$M$5:$X$10,7,FALSE) -> W | I4: =vlookup(E4,Data!$M$5:$X$10,8,FALSE) -> W | J4: =vlookup(E4,Data!$M$5:$X$10,9,FALSE) -> W | K4: =vlookup(E4,Data!$M$5:$X$10,10,FALSE) -> W
E5: =vlookup(E4,Source!$F$3:$K$18,2,FALSE) -> Ian's Team | G5: =vlookup(E4,Data!$M$5:$X$10,11,FALSE) -> W | H5: =vlookup(E4,Data!$M$5:$X$10,12,FALSE) -> W
C6: 2 | D6: =vlookup(E6,Source!$F$3:$K$18,5,FALSE) | E6: =Data!$AN$6 -> Zach VanSickle | F6: =CountIF(G6:K7,"W")&"-"&CountIF(G6:K7,"L") -> 4-3 | G6: =vlookup(E6,Data!$M$5:$X$10,6,FALSE) -> W | H6: =vlookup(E6,Data!$M$5:$X$10,7,FALSE) -> W | I6: =vlookup(E6,Data!$M$5:$X$10,8,FALSE) -> L | J6: =vlookup(E6,Data!$M$5:$X$10,9,FALSE) -> L | K6: =vlookup(E6,Data!$M$5:$X$10,10,FALSE) -> W
E7: =vlookup(E6,Source!$F$3:$K$18,2,FALSE) -> Zach's Team | G7: =vlookup(E6,Data!$M$5:$X$10,11,FALSE) -> W | H7: =vlookup(E6,Data!$M$5:$X$10,12,FALSE) -> L
C8: 3 | D8: =vlookup(E8,Source!$F$3:$K$18,5,FALSE) | E8: =Data!$AN$7 -> Tyler Gottfredsen | F8: =CountIF(G8:K9,"W")&"-"&CountIF(G8:K9,"L") -> 4-3 | G8: =vlookup(E8,Data!$M$5:$X$10,6,FALSE) -> L | H8: =vlookup(E8,Data!$M$5:$X$10,7,FALSE) -> L | I8: =vlookup(E8,Data!$M$5:$X$10,8,FALSE) -> W | J8: =vlookup(E8,Data!$M$5:$X$10,9,FALSE) -> W | K8: =vlookup(E8,Data!$M$5:$X$10,10,FALSE) -> L
E9: =vlookup(E8,Source!$F$3:$K$18,2,FALSE) -> Tyler's Team | G9: =vlookup(E8,Data!$M$5:$X$10,11,FALSE) -> W | H9: =vlookup(E8,Data!$M$5:$X$10,12,FALSE) -> W
C10: 4 | D10: =vlookup(E10,Source!$F$3:$K$18,5,FALSE) | E10: =Data!$AN$8 -> Jackson McLoughlin | F10: =CountIF(G10:K11,"W")&"-"&CountIF(G10:K11,"L") -> 3-4 | G10: =vlookup(E10,Data!$M$5:$X$10,6,FALSE) -> L | H10: =vlookup(E10,Data!$M$5:$X$10,7,FALSE) -> W | I10: =vlookup(E10,Data!$M$5:$X$10,8,FALSE) -> W | J10: =vlookup(E10,Data!$M$5:$X$10,9,FALSE) -> L | K10: =vlookup(E10,Data!$M$5:$X$10,10,FALSE) -> L
E11: =vlookup(E10,Source!$F$3:$K$18,2,FALSE) -> Jackson's Team | G11: =vlookup(E10,Data!$M$5:$X$10,11,FALSE) -> L | H11: =vlookup(E10,Data!$M$5:$X$10,12,FALSE) -> W
C12: 5 | D12: =vlookup(E12,Source!$F$3:$K$18,5,FALSE) | E12: =Data!$AN$9 -> Ryan Tidey | F12: =CountIF(G12:K13,"W")&"-"&CountIF(G12:K13,"L") -> 3-4 | G12: =vlookup(E12,Data!$M$5:$X$10,6,FALSE) -> W | H12: =vlookup(E12,Data!$M$5:$X$10,7,FALSE) -> L | I12: =vlookup(E12,Data!$M$5:$X$10,8,FALSE) -> L | J12: =vlookup(E12,Data!$M$5:$X$10,9,FALSE) -> W | K12: =vlookup(E12,Data!$M$5:$X$10,10,FALSE) -> W
E13: =vlookup(E12,Source!$F$3:$K$18,2,FALSE) -> Ryan's Team | G13: =vlookup(E12,Data!$M$5:$X$10,11,FALSE) -> L | H13: =vlookup(E12,Data!$M$5:$X$10,12,FALSE) -> L
C14: 6 | D14: =vlookup(E14,Source!$F$3:$K$18,5,FALSE) | E14: =Data!$AN$10 -> Dick Hansen | F14: =CountIF(G14:K15,"W")&"-"&CountIF(G14:K15,"L") -> 0-7 | G14: =vlookup(E14,Data!$M$5:$X$10,6,FALSE) -> L | H14: =vlookup(E14,Data!$M$5:$X$10,7,FALSE) -> L | I14: =vlookup(E14,Data!$M$5:$X$10,8,FALSE) -> L | J14: =vlookup(E14,Data!$M$5:$X$10,9,FALSE) -> L | K14: =vlookup(E14,Data!$M$5:$X$10,10,FALSE) -> L
E15: =vlookup(E14,Source!$F$3:$K$18,2,FALSE) -> Dick's Team | G15: =vlookup(E14,Data!$M$5:$X$10,11,FALSE) -> L | H15: =vlookup(E14,Data!$M$5:$X$10,12,FALSE) -> L

Sheet Draft Board
C3: Banned | F3: 25 Points | H3: DZ | I3: DO | K3: 24 Points | M3: DZ | N3: DO | P3: 23 Points | R3: DZ | S3: DO | U3: 22 Points | W3: DZ | X3: DO | Z3: 21 Points | AB3: DZ | AC3: DO | AE3: 20 Points | AG3: DZ | AH3: DO | AJ3: 19 Points | AL3: DZ | AM3: DO | AO3: 15 Points | AQ3: DZ | AT3: 13 Points | AV3: DZ | AY3: 12 Points | BA3: DZ | BD3: 10 Points | BF3: DZ | BI3: 9 Points | BK3: DZ | BN3: 8 Points | BP3: DZ | BS3: 6 Points | BU3: DZ | BX3: 5 Points | BZ3: DZ | CC3: 4 Points | CE3: DZ | CH3: 3 Points | CJ3: DZ | CM3: 1 Points | CO3: DZ
C5: {=IFERROR(VLOOKUP(D5:D353,Pokedex!$C$3:$D353,2,FALSE),"")} -> arceus | D5: Arceus | F5: =IFERROR(__xludf.DUMMYFUNCTION("IFERROR(SORT(FILTER(Source!$A$2:$B353,Source!$C$2:$C353=SPLIT(F3,"" Points"")),2,TRUE),"""")"),"") | H5: {=IF(COUNTIF(Data!$F$5:$F$71,G5:G7)>0,"X","-")} -> - | I5: {=IF(COUNTIF(#REF!,G5:G7)>0,"X","-")} -> - | K5: =IFERROR(__xludf.DUMMYFUNCTION("IFERROR(SORT(FILTER(Source!$A$2:$B353,Source!$C$2:$C353=SPLIT(K3,"" Points"")),2,TRUE),"""")"),"") | M5: {=IF(COUNTIF(Data!$F$5:$F$71,L5:L7)>0,"X","-")} -> - | N5: {=IF(COUNTIF(#REF!,L5:L7)>0,"X","-")} -> - | P5: =IFERROR(__xludf.DUMMYFUNCTION("IFERROR(SORT(FILTER(Source!$A$2:$B353,Source!$C$2:$C353=SPLIT(P3,"" Points"")),2,TRUE),"""")"),"") | R5: {=IF(COUNTIF(Data!$F$5:$F$71,Q5:Q7)>0,"X","-")} -> - | S5: {=IF(COUNTIF(#REF!,Q5:Q7)>0,"X","-")} -> - | U5: =IFERROR(__xludf.DUMMYFUNCTION("IFERROR(SORT(FILTER(Source!$A$2:$B353,Source!$C$2:$C353=SPLIT(U3,"" Points"")),2,TRUE),"""")"),"") | W5: {=IF(COUNTIF(Data!$F$5:$F$71,V5:V7)>0,"X","-")} -> - | X5: {=IF(COUNTIF(#REF!,V5:V7)>0,"X","-")} -> - | Z5: =IFERROR(__xludf.DUMMYFUNCTION("IFERROR(SORT(FILTER(Source!$A$2:$B353,Source!$C$2:$C353=SPLIT(Z3,"" Points"")),2,TRUE),"""")"),"") | AB5: {=IF(COUNTIF(Data!$F$5:$F$71,AA5:AA8)>0,"X","-")} -> - | AC5: {=IF(COUNTIF(#REF!,AA5:AA8)>0,"X","-")} -> - | AE5: =IFERROR(__xludf.DUMMYFUNCTION("IFERROR(SORT(FILTER(Source!$A$2:$B353,Source!$C$2:$C353=SPLIT(AE3,"" Points"")),2,TRUE),"""")"),"") | AG5: {=IF(COUNTIF(Data!$F$5:$F$71,AF5:AF8)>0,"X","-")} -> - | AH5: {=IF(COUNTIF(#REF!,AF5:AF8)>0,"X","-")} -> - | AJ5: =IFERROR(__xludf.DUMMYFUNCTION("IFERROR(SORT(FILTER(Source!$A$2:$B353,Source!$C$2:$C353=SPLIT(AJ3,"" Points"")),2,TRUE),"""")"),"") | AL5: {=IF(COUNTIF(Data!$F$5:$F$71,AK5:AK10)>0,"X","-")} -> - | AM5: {=IF(COUNTIF(#REF!,AK5:AK10)>0,"X","-")} -> - | AO5: =IFERROR(__xludf.DUMMYFUNCTION("IFERROR(SORT(FILTER(Source!$A$2:$B353,Source!$C$2:$C353=SPLIT(AO3,"" Points"")),2,TRUE),"""")"),"") | AP5: =IFERROR(__xludf.DUMMYFUNCTION("""COMPUTED_VALUE"""),"Gholdengo") -> Gholdengo | AQ5: {=IF(COUNTIF(Data!$F$5:$F$71,AP5:AP6)>0,"X","-")} -> X | AT5: =IFERROR(__xludf.DUMMYFUNCTION("IFERROR(SORT(FILTER(Source!$A$2:$B353,Source!$C$2:$C353=SPLIT(AT3,"" Points"")),2,TRUE),"""")"),"") | AU5: =IFERROR(__xludf.DUMMYFUNCTION("""COMPUTED_VALUE"""),"Annihilape") -> Annihilape | AV5: {=IF(COUNTIF(Data!$F$5:$F$71,AU5:AU6)>0,"X","-")} -> X | AY5: =IFERROR(__xludf.DUMMYFUNCTION("IFERROR(SORT(FILTER(Source!$A$2:$B353,Source!$C$2:$C353=SPLIT(AY3,"" Points"")),2,TRUE),"""")"),"") | AZ5: =IFERROR(__xludf.DUMMYFUNCTION("""COMPUTED_VALUE"""),"Amoonguss") -> Amoonguss | BA5: {=IF(COUNTIF(Data!$F$5:$F$71,AZ5:AZ9)>0,"X","-")} -> X | BD5: =IFERROR(__xludf.DUMMYFUNCTION("IFERROR(SORT(FILTER(Source!$A$2:$B353,Source!$C$2:$C353=SPLIT(BD3,"" Points"")),2,TRUE),"""")"),"") | BE5: =IFERROR(__xludf.DUMMYFUNCTION("""COMPUTED_VALUE"""),"Armarouge") -> Armarouge | BF5: {=IF(COUNTIF(Data!$F$5:$F$71,BE5:BE9)>0,"X","-")} -> X | BI5: =IFERROR(__xludf.DUMMYFUNCTION("IFERROR(SORT(FILTER(Source!$A$2:$B353,Source!$C$2:$C353=SPLIT(BI3,"" Points"")),2,TRUE),"""")"),"") | BJ5: =IFERROR(__xludf.DUMMYFUNCTION("""COMPUTED_VALUE"""),"Arcanine") -> Arcanine | BK5: {=IF(COUNTIF(Data!$F$5:$F$71,BJ5:BJ10)>0,"X","-")} -> X | BN5: =IFERROR(__xludf.DUMMYFUNCTION("IFERROR(SORT(FILTER(Source!$A$2:$B353,Source!$C$2:$C353=SPLIT(BN3,"" Points"")),2,TRUE),"""")"),"") | BO5: =IFERROR(__xludf.DUMMYFUNCTION("""COMPUTED_VALUE"""),"Baxcalibur") -> Baxcalibur | BP5: {=IF(COUNTIF(Data!$F$5:$F$71,BO5:BO15)>0,"X","-")} -> X | BS5: =IFERROR(__xludf.DUMMYFUNCTION("IFERROR(SORT(FILTER(Source!$A$2:$B353,Source!$C$2:$C353=SPLIT(BS3,"" Points"")),2,TRUE),"""")"),"") | BT5: =IFERROR(__xludf.DUMMYFUNCTION("""COMPUTED_VALUE"""),"Ceruledge") -> Ceruledge | BU5: {=IF(COUNTIF(Data!$F$5:$F$71,BT5:BT16)>0,"X","-")} -> - | BX5: =IFERROR(__xludf.DUMMYFUNCTION("IFERROR(SORT(FILTER(Source!$A$2:$B353,Source!$C$2:$C353=SPLIT(BX3,"" Points"")),2,TRUE),"""")"),"") | BY5: =IFERROR(__xludf.DUMMYFUNCTION("""COMPUTED_VALUE"""),"Abomasnow") -> Abomasnow | BZ5: {=IF(COUNTIF(Data!$F$5:$F$71,BY5:BY15)>0,"X","-")} -> X | CC5: =IFERROR(__xludf.DUMMYFUNCTION("IFERROR(SORT(FILTER(Source!$A$2:$B353,Source!$C$2:$C353=SPLIT(CC3,"" Points"")),2,TRUE),"""")"),"") | CD5: =IFERROR(__xludf.DUMMYFUNCTION("""COMPUTED_VALUE"""),"Arboliva") -> Arboliva | CE5: {=IF(COUNTIF(Data!$F$5:$F$71,CD5:CD21)>0,"X","-")} -> X | CH5: =IFERROR(__xludf.DUMMYFUNCTION("IFERROR(SORT(FILTER(Source!$A$2:$B353,Source!$C$2:$C353=SPLIT(CH3,"" Points"")),2,TRUE),"""")"),"") | CI5: =IFERROR(__xludf.DUMMYFUNCTION("""COMPUTED_VALUE"""),"Beartic") -> Beartic | CJ5: {=IF(COUNTIF(Data!$F$5:$F$71,CI5:CI35)>0,"X","-")} -> - | CM5: =IFERROR(__xludf.DUMMYFUNCTION("IFERROR(SORT(FILTER(Source!$A$2:$B353,Source!$C$2:$C353=SPLIT(CM3,"" Points"")),2,TRUE),"""")"),"") | CN5: =IFERROR(__xludf.DUMMYFUNCTION("""COMPUTED_VALUE"""),"Alomomola") -> Alomomola | CO5: {=IF(COUNTIF(Data!$F$5:$F$71,CN5:CN281)>0,"X","-")} -> -
C6: calyrex-ice | D6: Calyrex-Ice | H6: - | I6: - | M6: - | N6: - | R6: - | S6: - | W6: - | X6: - | AB6: - | AC6: - | AG6: - | AH6: - | AL6: - | AM6: - | AO6: =IFERROR(__xludf.DUMMYFUNCTION("""COMPUTED_VALUE"""),"") | AP6: =IFERROR(__xludf.DUMMYFUNCTION("""COMPUTED_VALUE"""),"Meowscarada") -> Meowscarada | AQ6: X | AT6: =IFERROR(__xludf.DUMMYFUNCTION("""COMPUTED_VALUE"""),"") | AU6: =IFERROR(__xludf.DUMMYFUNCTION("""COMPUTED_VALUE"""),"Sylveon") -> Sylveon | AV6: X | AY6: =IFERROR(__xludf.DUMMYFUNCTION("""COMPUTED_VALUE"""),"") | AZ6: =IFERROR(__xludf.DUMMYFUNCTION("""COMPUTED_VALUE"""),"Dondozo") -> Dondozo | BA6: X | BD6: =IFERROR(__xludf.DUMMYFUNCTION("""COMPUTED_VALUE"""),"") | BE6: =IFERROR(__xludf.DUMMYFUNCTION("""COMPUTED_VALUE"""),"Garchomp") -> Garchomp | BF6: X | BI6: =IFERROR(__xludf.DUMMYFUNCTION("""COMPUTED_VALUE"""),"") | BJ6: =IFERROR(__xludf.DUMMYFUNCTION("""COMPUTED_VALUE"""),"Azumarill") -> Azumarill | BK6: X | BN6: =IFERROR(__xludf.DUMMYFUNCTION("""COMPUTED_VALUE"""),"") | BO6: =IFERROR(__xludf.DUMMYFUNCTION("""COMPUTED_VALUE"""),"Garganacl") -> Garganacl | BP6: X | BS6: =IFERROR(__xludf.DUMMYFUNCTION("""COMPUTED_VALUE"""),"") | BT6: =IFERROR(__xludf.DUMMYFUNCTION("""COMPUTED_VALUE"""),"Dragapult") -> Dragapult | BU6: X | BX6: =IFERROR(__xludf.DUMMYFUNCTION("""COMPUTED_VALUE"""),"") | BY6: =IFERROR(__xludf.DUMMYFUNCTION("""COMPUTED_VALUE"""),"Breloom") -> Breloom | BZ6: - | CC6: =IFERROR(__xludf.DUMMYFUNCTION("""COMPUTED_VALUE"""),"") | CD6: =IFERROR(__xludf.DUMMYFUNCTION("""COMPUTED_VALUE"""),"Avalugg") -> Avalugg | CE6: - | CH6: =IFERROR(__xludf.DUMMYFUNCTION("""COMPUTED_VALUE"""),"") | CI6: =IFERROR(__xludf.DUMMYFUNCTION("""COMPUTED_VALUE"""),"Brambleghast") -> Brambleghast | CJ6: - | CM6: =IFERROR(__xludf.DUMMYFUNCTION("""COMPUTED_VALUE"""),"") | CN6: =IFERROR(__xludf.DUMMYFUNCTION("""COMPUTED_VALUE"""),"Altaria") -> Altaria | CO6: -
C7: calyrex-shadow | D7: Calyrex-Shadow | H7: - | I7: - | M7: - | N7: - | R7: - | S7: - | W7: - | X7: - | AB7: - | AC7: - | AG7: - | AH7: - | AL7: - | AM7: - | AY7: =IFERROR(__xludf.DUMMYFUNCTION("""COMPUTED_VALUE"""),"") | AZ7: =IFERROR(__xludf.DUMMYFUNCTION("""COMPUTED_VALUE"""),"Hydreigon") -> Hydreigon | BA7: X | BD7: =IFERROR(__xludf.DUMMYFUNCTION("""COMPUTED_VALUE"""),"") | BE7: =IFERROR(__xludf.DUMMYFUNCTION("""COMPUTED_VALUE"""),"Grimmsnarl") -> Grimmsnarl | BF7: - | BI7: =IFERROR(__xludf.DUMMYFUNCTION("""COMPUTED_VALUE"""),"") | BJ7: =IFERROR(__xludf.DUMMYFUNCTION("""COMPUTED_VALUE"""),"Dragonite") -> Dragonite | BK7: X | BN7: =IFERROR(__xludf.DUMMYFUNCTION("""COMPUTED_VALUE"""),"") | BO7: =IFERROR(__xludf.DUMMYFUNCTION("""COMPUTED_VALUE"""),"Indeedee-Male") -> Indeedee-Male | BP7: - | BS7: =IFERROR(__xludf.DUMMYFUNCTION("""COMPUTED_VALUE"""),"") | BT7: =IFERROR(__xludf.DUMMYFUNCTION("""COMPUTED_VALUE"""),"Farigiraf") -> Farigiraf | BU7: X | BX7: =IFERROR(__xludf.DUMMYFUNCTION("""COMPUTED_VALUE"""),"") | BY7: =IFERROR(__xludf.DUMMYFUNCTION("""COMPUTED_VALUE"""),"Flamigo") -> Flamigo | BZ7: X | CC7: =IFERROR(__xludf.DUMMYFUNCTION("""COMPUTED_VALUE"""),"") | CD7: =IFERROR(__xludf.DUMMYFUNCTION("""COMPUTED_VALUE"""),"Barraskewda") -> Barraskewda | CE7: - | CH7: =IFERROR(__xludf.DUMMYFUNCTION("""COMPUTED_VALUE"""),"") | CI7: =IFERROR(__xludf.DUMMYFUNCTION("""COMPUTED_VALUE"""),"Bronzong") -> Bronzong | CJ7: - | CM7: =IFERROR(__xludf.DUMMYFUNCTION("""COMPUTED_VALUE"""),"") | CN7: =IFERROR(__xludf.DUMMYFUNCTION("""COMPUTED_VALUE"""),"Ampharos") -> Ampharos | CO7: -
C8: dialga | D8: Dialga | M8: X | N8: X | W8: - | X8: - | AB8: - | AC8: - | AG8: - | AH8: - | AL8: - | AM8: - | AY8: =IFERROR(__xludf.DUMMYFUNCTION("""COMPUTED_VALUE"""),"") | AZ8: =IFERROR(__xludf.DUMMYFUNCTION("""COMPUTED_VALUE"""),"Murkrow") -> Murkrow | BA8: X | BD8: =IFERROR(__xludf.DUMMYFUNCTION("""COMPUTED_VALUE"""),"") | BE8: =IFERROR(__xludf.DUMMYFUNCTION("""COMPUTED_VALUE"""),"Kingambit") -> Kingambit | BF8: X | BI8: =IFERROR(__xludf.DUMMYFUNCTION("""COMPUTED_VALUE"""),"") | BJ8: =IFERROR(__xludf.DUMMYFUNCTION("""COMPUTED_VALUE"""),"Indeedee-Female") -> Indeedee-Female | BK8: X | BN8: =IFERROR(__xludf.DUMMYFUNCTION("""COMPUTED_VALUE"""),"") | BO8: =IFERROR(__xludf.DUMMYFUNCTION("""COMPUTED_VALUE"""),"Mimikyu") -> Mimikyu | BP8: X | BS8: =IFERROR(__xludf.DUMMYFUNCTION("""COMPUTED_VALUE"""),"") | BT8: =IFERROR(__xludf.DUMMYFUNCTION("""COMPUTED_VALUE"""),"Gallade") -> Gallade | BU8: X | BX8: =IFERROR(__xludf.DUMMYFUNCTION("""COMPUTED_VALUE"""),"") | BY8: =IFERROR(__xludf.DUMMYFUNCTION("""COMPUTED_VALUE"""),"Gardevoir") -> Gardevoir | BZ8: - | CC8: =IFERROR(__xludf.DUMMYFUNCTION("""COMPUTED_VALUE"""),"") | CD8: =IFERROR(__xludf.DUMMYFUNCTION("""COMPUTED_VALUE"""),"Bellibolt") -> Bellibolt | CE8: - | CH8: =IFERROR(__xludf.DUMMYFUNCTION("""COMPUTED_VALUE"""),"") | CI8: =IFERROR(__xludf.DUMMYFUNCTION("""COMPUTED_VALUE"""),"Coalossal") -> Coalossal | CJ8: - | CM8: =IFERROR(__xludf.DUMMYFUNCTION("""COMPUTED_VALUE"""),"") | CN8: =IFERROR(__xludf.DUMMYFUNCTION("""COMPUTED_VALUE"""),"Appletun") -> Appletun | CO8: -
C9: eternatus | D9: Eternatus | M9: - | N9: - | AL9: - | AM9: - | AY9: =IFERROR(__xludf.DUMMYFUNCTION("""COMPUTED_VALUE"""),"") | AZ9: =IFERROR(__xludf.DUMMYFUNCTION("""COMPUTED_VALUE"""),"Tatsugiri") -> Tatsugiri | BA9: X | BD9: =IFERROR(__xludf.DUMMYFUNCTION("""COMPUTED_VALUE"""),"") | BE9: =IFERROR(__xludf.DUMMYFUNCTION("""COMPUTED_VALUE"""),"Maushold") -> Maushold | BF9: X | BI9: =IFERROR(__xludf.DUMMYFUNCTION("""COMPUTED_VALUE"""),"") | BJ9: =IFERROR(__xludf.DUMMYFUNCTION("""COMPUTED_VALUE"""),"Talonflame") -> Talonflame | BK9: X | BN9: =IFERROR(__xludf.DUMMYFUNCTION("""COMPUTED_VALUE"""),"") | BO9: =IFERROR(__xludf.DUMMYFUNCTION("""COMPUTED_VALUE"""),"Palafin") -> Palafin | BP9: X | BS9: =IFERROR(__xludf.DUMMYFUNCTION("""COMPUTED_VALUE"""),"") | BT9: =IFERROR(__xludf.DUMMYFUNCTION("""COMPUTED_VALUE"""),"Gengar") -> Gengar | BU9: X | BX9: =IFERROR(__xludf.DUMMYFUNCTION("""COMPUTED_VALUE"""),"") | BY9: =IFERROR(__xludf.DUMMYFUNCTION("""COMPUTED_VALUE"""),"Gastrodon") -> Gastrodon | BZ9: X | CC9: =IFERROR(__xludf.DUMMYFUNCTION("""COMPUTED_VALUE"""),"") | CD9: =IFERROR(__xludf.DUMMYFUNCTION("""COMPUTED_VALUE"""),"Cetitan") -> Cetitan | CE9: X | CH9: =IFERROR(__xludf.DUMMYFUNCTION("""COMPUTED_VALUE"""),"") | CI9: =IFERROR(__xludf.DUMMYFUNCTION("""COMPUTED_VALUE"""),"Cyclizar") -> Cyclizar | CJ9: - | CM9: =IFERROR(__xludf.DUMMYFUNCTION("""COMPUTED_VALUE"""),"") | CN9: =IFERROR(__xludf.DUMMYFUNCTION("""COMPUTED_VALUE"""),"Applin") -> Applin | CO9: -
C10: giratina | D10: Giratina | AL10: - | AM10: - | BI10: =IFERROR(__xludf.DUMMYFUNCTION("""COMPUTED_VALUE"""),"") | BJ10: =IFERROR(__xludf.DUMMYFUNCTION("""COMPUTED_VALUE"""),"Volcarona") -> Volcarona | BK10: X | BN10: =IFERROR(__xludf.DUMMYFUNCTION("""COMPUTED_VALUE"""),"") | BO10: =IFERROR(__xludf.DUMMYFUNCTION("""COMPUTED_VALUE"""),"Paldean Tauros (Fire)") -> Paldean Tauros (Fire) | BP10: X | BS10: =IFERROR(__xludf.DUMMYFUNCTION("""COMPUTED_VALUE"""),"") | BT10: =IFERROR(__xludf.DUMMYFUNCTION("""COMPUTED_VALUE"""),"Gothitelle") -> Gothitelle | BU10: X | BX10: =IFERROR(__xludf.DUMMYFUNCTION("""COMPUTED_VALUE"""),"") | BY10: =IFERROR(__xludf.DUMMYFUNCTION("""COMPUTED_VALUE"""),"Gyarados") -> Gyarados | BZ10: - | CC10: =IFERROR(__xludf.DUMMYFUNCTION("""COMPUTED_VALUE"""),"") | CD10: =IFERROR(__xludf.DUMMYFUNCTION("""COMPUTED_VALUE"""),"Clodsire") -> Clodsire | CE10: - | CH10: =IFERROR(__xludf.DUMMYFUNCTION("""COMPUTED_VALUE"""),"") | CI10: =IFERROR(__xludf.DUMMYFUNCTION("""COMPUTED_VALUE"""),"Dachsbun") -> Dachsbun | CJ10: - | CM10: =IFERROR(__xludf.DUMMYFUNCTION("""COMPUTED_VALUE"""),"") | CN10: =IFERROR(__xludf.DUMMYFUNCTION("""COMPUTED_VALUE"""),"Arctibax") -> Arctibax | CO10: -
C11: giratina-origin | D11: Giratina-Origin | AL11: - | AM11: - | BN11: =IFERROR(__xludf.DUMMYFUNCTION("""COMPUTED_VALUE"""),"") | BO11: =IFERROR(__xludf.DUMMYFUNCTION("""COMPUTED_VALUE"""),"Paldean Tauros (Water)") -> Paldean Tauros (Water) | BP11: - | BS11: =IFERROR(__xludf.DUMMYFUNCTION("""COMPUTED_VALUE"""),"") | BT11: =IFERROR(__xludf.DUMMYFUNCTION("""COMPUTED_VALUE"""),"Hariyama") -> Hariyama | BU11: X | BX11: =IFERROR(__xludf.DUMMYFUNCTION("""COMPUTED_VALUE"""),"") | BY11: =IFERROR(__xludf.DUMMYFUNCTION("""COMPUTED_VALUE"""),"Jumpluff") -> Jumpluff | BZ11: - | CC11: =IFERROR(__xludf.DUMMYFUNCTION("""COMPUTED_VALUE"""),"") | CD11: =IFERROR(__xludf.DUMMYFUNCTION("""COMPUTED_VALUE"""),"Corviknight") -> Corviknight | CE11: - | CH11: =IFERROR(__xludf.DUMMYFUNCTION("""COMPUTED_VALUE"""),"") | CI11: =IFERROR(__xludf.DUMMYFUNCTION("""COMPUTED_VALUE"""),"Donphan") -> Donphan | CJ11: - | CM11: =IFERROR(__xludf.DUMMYFUNCTION("""COMPUTED_VALUE"""),"") | CN11: =IFERROR(__xludf.DUMMYFUNCTION("""COMPUTED_VALUE"""),"Arrokuda") -> Arrokuda | CO11: -
C12: groudon | D12: Groudon | BN12: =IFERROR(__xludf.DUMMYFUNCTION("""COMPUTED_VALUE"""),"") | BO12: =IFERROR(__xludf.DUMMYFUNCTION("""COMPUTED_VALUE"""),"Pelipper") -> Pelipper | BP12: X | BS12: =IFERROR(__xludf.DUMMYFUNCTION("""COMPUTED_VALUE"""),"") | BT12: =IFERROR(__xludf.DUMMYFUNCTION("""COMPUTED_VALUE"""),"Kilowattrel") -> Kilowattrel | BU12: X | BX12: =IFERROR(__xludf.DUMMYFUNCTION("""COMPUTED_VALUE"""),"") | BY12: =IFERROR(__xludf.DUMMYFUNCTION("""COMPUTED_VALUE"""),"Oranguru") -> Oranguru | BZ12: X | CC12: =IFERROR(__xludf.DUMMYFUNCTION("""COMPUTED_VALUE"""),"") | CD12: =IFERROR(__xludf.DUMMYFUNCTION("""COMPUTED_VALUE"""),"Cryogonal") -> Cryogonal | CE12: - | CH12: =IFERROR(__xludf.DUMMYFUNCTION("""COMPUTED_VALUE"""),"") | CI12: =IFERROR(__xludf.DUMMYFUNCTION("""COMPUTED_VALUE"""),"Dragalge") -> Dragalge | CJ12: - | CM12: =IFERROR(__xludf.DUMMYFUNCTION("""COMPUTED_VALUE"""),"") | CN12: =IFERROR(__xludf.DUMMYFUNCTION("""COMPUTED_VALUE"""),"Axew") -> Axew | CO12: -
C13: groudon-primal | D13: Groudon-Primal | BN13: =IFERROR(__xludf.DUMMYFUNCTION("""COMPUTED_VALUE"""),"") | BO13: =IFERROR(__xludf.DUMMYFUNCTION("""COMPUTED_VALUE"""),"Skeledirge") -> Skeledirge | BP13: X | BS13: =IFERROR(__xludf.DUMMYFUNCTION("""COMPUTED_VALUE"""),"") | BT13: =IFERROR(__xludf.DUMMYFUNCTION("""COMPUTED_VALUE"""),"Lycanroc-Dusk") -> Lycanroc-Dusk | BU13: X | BX13: =IFERROR(__xludf.DUMMYFUNCTION("""COMPUTED_VALUE"""),"") | BY13: =IFERROR(__xludf.DUMMYFUNCTION("""COMPUTED_VALUE"""),"Quaquaval") -> Quaquaval | BZ13: X | CC13: =IFERROR(__xludf.DUMMYFUNCTION("""COMPUTED_VALUE"""),"") | CD13: =IFERROR(__xludf.DUMMYFUNCTION("""COMPUTED_VALUE"""),"Drednaw") -> Drednaw | CE13: - | CH13: =IFERROR(__xludf.DUMMYFUNCTION("""COMPUTED_VALUE"""),"") | CI13: =IFERROR(__xludf.DUMMYFUNCTION("""COMPUTED_VALUE"""),"Drifblim") -> Drifblim | CJ13: - | CM13: =IFERROR(__xludf.DUMMYFUNCTION("""COMPUTED_VALUE"""),"") | CN13: =IFERROR(__xludf.DUMMYFUNCTION("""COMPUTED_VALUE"""),"Bagon") -> Bagon | CO13: -
C14: hooh | D14: Ho-Oh | BN14: =IFERROR(__xludf.DUMMYFUNCTION("""COMPUTED_VALUE"""),"") | BO14: =IFERROR(__xludf.DUMMYFUNCTION("""COMPUTED_VALUE"""),"Torkoal") -> Torkoal | BP14: X | BS14: =IFERROR(__xludf.DUMMYFUNCTION("""COMPUTED_VALUE"""),"") | BT14: =IFERROR(__xludf.DUMMYFUNCTION("""COMPUTED_VALUE"""),"Pawmot") -> Pawmot | BU14: X | BX14: =IFERROR(__xludf.DUMMYFUNCTION("""COMPUTED_VALUE"""),"") | BY14: =IFERROR(__xludf.DUMMYFUNCTION("""COMPUTED_VALUE"""),"Salamence") -> Salamence | BZ14: X | CC14: =IFERROR(__xludf.DUMMYFUNCTION("""COMPUTED_VALUE"""),"") | CD14: =IFERROR(__xludf.DUMMYFUNCTION("""COMPUTED_VALUE"""),"Floatzel") -> Floatzel | CE14: - | CH14: =IFERROR(__xludf.DUMMYFUNCTION("""COMPUTED_VALUE"""),"") | CI14: =IFERROR(__xludf.DUMMYFUNCTION("""COMPUTED_VALUE"""),"Dudunsparce") -> Dudunsparce | CJ14: - | CM14: =IFERROR(__xludf.DUMMYFUNCTION("""COMPUTED_VALUE"""),"") | CN14: =IFERROR(__xludf.DUMMYFUNCTION("""COMPUTED_VALUE"""),"Banette") -> Banette | CO14: -
C15: kyogre | D15: Kyogre | BN15: =IFERROR(__xludf.DUMMYFUNCTION("""COMPUTED_VALUE"""),"") | BO15: =IFERROR(__xludf.DUMMYFUNCTION("""COMPUTED_VALUE"""),"Tyranitar") -> Tyranitar | BP15: X | BS15: =IFERROR(__xludf.DUMMYFUNCTION("""COMPUTED_VALUE"""),"") | BT15: =IFERROR(__xludf.DUMMYFUNCTION("""COMPUTED_VALUE"""),"Rotom-Heat") -> Rotom-Heat | BU15: - | BX15: =IFERROR(__xludf.DUMMYFUNCTION("""COMPUTED_VALUE"""),"") | BY15: =IFERROR(__xludf.DUMMYFUNCTION("""COMPUTED_VALUE"""),"Tinkaton") -> Tinkaton | BZ15: - | CC15: =IFERROR(__xludf.DUMMYFUNCTION("""COMPUTED_VALUE"""),"") | CD15: =IFERROR(__xludf.DUMMYFUNCTION("""COMPUTED_VALUE"""),"Glimmora") -> Glimmora | CE15: - | CH15: =IFERROR(__xludf.DUMMYFUNCTION("""COMPUTED_VALUE"""),"") | CI15: =IFERROR(__xludf.DUMMYFUNCTION("""COMPUTED_VALUE"""),"Espathra") -> Espathra | CJ15: X | CM15: =IFERROR(__xludf.DUMMYFUNCTION("""COMPUTED_VALUE"""),"") | CN15: =IFERROR(__xludf.DUMMYFUNCTION("""COMPUTED_VALUE"""),"Barboach") -> Barboach | CO15: -
C16: kyogre-primal | D16: Kyogre-Primal | BS16: =IFERROR(__xludf.DUMMYFUNCTION("""COMPUTED_VALUE"""),"") | BT16: =IFERROR(__xludf.DUMMYFUNCTION("""COMPUTED_VALUE"""),"Rotom-Wash") -> Rotom-Wash | BU16: - | CC16: =IFERROR(__xludf.DUMMYFUNCTION("""COMPUTED_VALUE"""),"") | CD16: =IFERROR(__xludf.DUMMYFUNCTION("""COMPUTED_VALUE"""),"Hatterene") -> Hatterene | CE16: - | CH16: =IFERROR(__xludf.DUMMYFUNCTION("""COMPUTED_VALUE"""),"") | CI16: =IFERROR(__xludf.DUMMYFUNCTION("""COMPUTED_VALUE"""),"Goodra") -> Goodra | CJ16: - | CM16: =IFERROR(__xludf.DUMMYFUNCTION("""COMPUTED_VALUE"""),"") | CN16: =IFERROR(__xludf.DUMMYFUNCTION("""COMPUTED_VALUE"""),"Basculin") -> Basculin | CO16: -
C17: kyurem-black | D17: Kyurem-Black | CC17: =IFERROR(__xludf.DUMMYFUNCTION("""COMPUTED_VALUE"""),"") | CD17: =IFERROR(__xludf.DUMMYFUNCTION("""COMPUTED_VALUE"""),"Salazzle") -> Salazzle | CE17: - | CH17: =IFERROR(__xludf.DUMMYFUNCTION("""COMPUTED_VALUE"""),"") | CI17: =IFERROR(__xludf.DUMMYFUNCTION("""COMPUTED_VALUE"""),"Gothorita") -> Gothorita | CJ17: - | CM17: =IFERROR(__xludf.DUMMYFUNCTION("""COMPUTED_VALUE"""),"") | CN17: =IFERROR(__xludf.DUMMYFUNCTION("""COMPUTED_VALUE"""),"Bergmite") -> Bergmite | CO17: -
C18: kyurem-white | D18: Kyurem-White | CC18: =IFERROR(__xludf.DUMMYFUNCTION("""COMPUTED_VALUE"""),"") | CD18: =IFERROR(__xludf.DUMMYFUNCTION("""COMPUTED_VALUE"""),"Scizor") -> Scizor | CE18: X | CH18: =IFERROR(__xludf.DUMMYFUNCTION("""COMPUTED_VALUE"""),"") | CI18: =IFERROR(__xludf.DUMMYFUNCTION("""COMPUTED_VALUE"""),"Grafaiai") -> Grafaiai | CJ18: X | CM18: =IFERROR(__xludf.DUMMYFUNCTION("""COMPUTED_VALUE"""),"") | CN18: =IFERROR(__xludf.DUMMYFUNCTION("""COMPUTED_VALUE"""),"Bisharp") -> Bisharp | CO18: -
C19: lugia | D19: Lugia | CC19: =IFERROR(__xludf.DUMMYFUNCTION("""COMPUTED_VALUE"""),"") | CD19: =IFERROR(__xludf.DUMMYFUNCTION("""COMPUTED_VALUE"""),"Toxapex") -> Toxapex | CE19: X | CH19: =IFERROR(__xludf.DUMMYFUNCTION("""COMPUTED_VALUE"""),"") | CI19: =IFERROR(__xludf.DUMMYFUNCTION("""COMPUTED_VALUE"""),"Houndstone") -> Houndstone | CJ19: - | CM19: =IFERROR(__xludf.DUMMYFUNCTION("""COMPUTED_VALUE"""),"") | CN19: =IFERROR(__xludf.DUMMYFUNCTION("""COMPUTED_VALUE"""),"Blissey") -> Blissey | CO19: -
C20: lunala | D20: Lunala | CC20: =IFERROR(__xludf.DUMMYFUNCTION("""COMPUTED_VALUE"""),"") | CD20: =IFERROR(__xludf.DUMMYFUNCTION("""COMPUTED_VALUE"""),"Tsareena") -> Tsareena | CE20: - | CH20: =IFERROR(__xludf.DUMMYFUNCTION("""COMPUTED_VALUE"""),"") | CI20: =IFERROR(__xludf.DUMMYFUNCTION("""COMPUTED_VALUE"""),"Lilligant") -> Lilligant | CJ20: X | CM20: =IFERROR(__xludf.DUMMYFUNCTION("""COMPUTED_VALUE"""),"") | CN20: =IFERROR(__xludf.DUMMYFUNCTION("""COMPUTED_VALUE"""),"Bombirdier") -> Bombirdier | CO20: -
C21: magearna | D21: Magearna | CC21: =IFERROR(__xludf.DUMMYFUNCTION("""COMPUTED_VALUE"""),"") | CD21: =IFERROR(__xludf.DUMMYFUNCTION("""COMPUTED_VALUE"""),"Vaporeon") -> Vaporeon | CE21: - | CH21: =IFERROR(__xludf.DUMMYFUNCTION("""COMPUTED_VALUE"""),"") | CI21: =IFERROR(__xludf.DUMMYFUNCTION("""COMPUTED_VALUE"""),"Magnezone") -> Magnezone | CJ21: X | CM21: =IFERROR(__xludf.DUMMYFUNCTION("""COMPUTED_VALUE"""),"") | CN21: =IFERROR(__xludf.DUMMYFUNCTION("""COMPUTED_VALUE"""),"Bounsweet") -> Bounsweet | CO21: -
C22: mewtwo | D22: Mewtwo | CH22: =IFERROR(__xludf.DUMMYFUNCTION("""COMPUTED_VALUE"""),"") | CI22: =IFERROR(__xludf.DUMMYFUNCTION("""COMPUTED_VALUE"""),"Mismagius") -> Mismagius | CJ22: - | CM22: =IFERROR(__xludf.DUMMYFUNCTION("""COMPUTED_VALUE"""),"") | CN22: =IFERROR(__xludf.DUMMYFUNCTION("""COMPUTED_VALUE"""),"Bramblin") -> Bramblin | CO22: -
D23: Mewtwo-Mega X | CH23: =IFERROR(__xludf.DUMMYFUNCTION("""COMPUTED_VALUE"""),"") | CI23: =IFERROR(__xludf.DUMMYFUNCTION("""COMPUTED_VALUE"""),"Mudsdale") -> Mudsdale | CJ23: X | CM23: =IFERROR(__xludf.DUMMYFUNCTION("""COMPUTED_VALUE"""),"") | CN23: =IFERROR(__xludf.DUMMYFUNCTION("""COMPUTED_VALUE"""),"Braviary") -> Braviary | CO23: -
D24: Mewtwo-Mega Y | CH24: =IFERROR(__xludf.DUMMYFUNCTION("""COMPUTED_VALUE"""),"") | CI24: =IFERROR(__xludf.DUMMYFUNCTION("""COMPUTED_VALUE"""),"Noivern") -> Noivern | CJ24: - | CM24: =IFERROR(__xludf.DUMMYFUNCTION("""COMPUTED_VALUE"""),"") | CN24: =IFERROR(__xludf.DUMMYFUNCTION("""COMPUTED_VALUE"""),"Bronzor") -> Bronzor | CO24: -
C25: necrozma-dawnwings | D25: Necrozma-Dawn | CH25: =IFERROR(__xludf.DUMMYFUNCTION("""COMPUTED_VALUE"""),"") | CI25: =IFERROR(__xludf.DUMMYFUNCTION("""COMPUTED_VALUE"""),"Orthworm") -> Orthworm | CJ25: X | CM25: =IFERROR(__xludf.DUMMYFUNCTION("""COMPUTED_VALUE"""),"") | CN25: =IFERROR(__xludf.DUMMYFUNCTION("""COMPUTED_VALUE"""),"Bruxish") -> Bruxish | CO25: -
C26: necrozma-duskmane | D26: Necrozma-Dusk | CH26: =IFERROR(__xludf.DUMMYFUNCTION("""COMPUTED_VALUE"""),"") | CI26: =IFERROR(__xludf.DUMMYFUNCTION("""COMPUTED_VALUE"""),"Pachirisu") -> Pachirisu | CJ26: X | CM26: =IFERROR(__xludf.DUMMYFUNCTION("""COMPUTED_VALUE"""),"") | CN26: =IFERROR(__xludf.DUMMYFUNCTION("""COMPUTED_VALUE"""),"Buizel") -> Buizel | CO26: -
C27: necrozma-ultra | D27: Necrozma-Ultra | CH27: =IFERROR(__xludf.DUMMYFUNCTION("""COMPUTED_VALUE"""),"") | CI27: =IFERROR(__xludf.DUMMYFUNCTION("""COMPUTED_VALUE"""),"Rabsca") -> Rabsca | CJ27: - | CM27: =IFERROR(__xludf.DUMMYFUNCTION("""COMPUTED_VALUE"""),"") | CN27: =IFERROR(__xludf.DUMMYFUNCTION("""COMPUTED_VALUE"""),"Cacnea") -> Cacnea | CO27: -
C28: palkia | D28: Palkia | CH28: =IFERROR(__xludf.DUMMYFUNCTION("""COMPUTED_VALUE"""),"") | CI28: =IFERROR(__xludf.DUMMYFUNCTION("""COMPUTED_VALUE"""),"Raichu") -> Raichu | CJ28: X | CM28: =IFERROR(__xludf.DUMMYFUNCTION("""COMPUTED_VALUE"""),"") | CN28: =IFERROR(__xludf.DUMMYFUNCTION("""COMPUTED_VALUE"""),"Cacturne") -> Cacturne | CO28: -
C29: rayquaza | D29: Rayquaza | CH29: =IFERROR(__xludf.DUMMYFUNCTION("""COMPUTED_VALUE"""),"") | CI29: =IFERROR(__xludf.DUMMYFUNCTION("""COMPUTED_VALUE"""),"Rotom-Mow") -> Rotom-Mow | CJ29: - | CM29: =IFERROR(__xludf.DUMMYFUNCTION("""COMPUTED_VALUE"""),"") | CN29: =IFERROR(__xludf.DUMMYFUNCTION("""COMPUTED_VALUE"""),"Camerupt") -> Camerupt | CO29: X
C30: reshiram | D30: Reshiram | CH30: =IFERROR(__xludf.DUMMYFUNCTION("""COMPUTED_VALUE"""),"") | CI30: =IFERROR(__xludf.DUMMYFUNCTION("""COMPUTED_VALUE"""),"Sableye") -> Sableye | CJ30: - | CM30: =IFERROR(__xludf.DUMMYFUNCTION("""COMPUTED_VALUE"""),"") | CN30: =IFERROR(__xludf.DUMMYFUNCTION("""COMPUTED_VALUE"""),"Capsakid") -> Capsakid | CO30: -
C31: solgaleo | D31: Solgaleo | CH31: =IFERROR(__xludf.DUMMYFUNCTION("""COMPUTED_VALUE"""),"") | CI31: =IFERROR(__xludf.DUMMYFUNCTION("""COMPUTED_VALUE"""),"Scovillain") -> Scovillain | CJ31: - | CM31: =IFERROR(__xludf.DUMMYFUNCTION("""COMPUTED_VALUE"""),"") | CN31: =IFERROR(__xludf.DUMMYFUNCTION("""COMPUTED_VALUE"""),"Carkol") -> Carkol | CO31: -
C32: xerneas | D32: Xerneas | CH32: =IFERROR(__xludf.DUMMYFUNCTION("""COMPUTED_VALUE"""),"") | CI32: =IFERROR(__xludf.DUMMYFUNCTION("""COMPUTED_VALUE"""),"Slaking") -> Slaking | CJ32: X | CM32: =IFERROR(__xludf.DUMMYFUNCTION("""COMPUTED_VALUE"""),"") | CN32: =IFERROR(__xludf.DUMMYFUNCTION("""COMPUTED_VALUE"""),"Cetoddle") -> Cetoddle | CO32: -
C33: yveltal | D33: Yveltal | CH33: =IFERROR(__xludf.DUMMYFUNCTION("""COMPUTED_VALUE"""),"") | CI33: =IFERROR(__xludf.DUMMYFUNCTION("""COMPUTED_VALUE"""),"Slowking") -> Slowking | CJ33: - | CM33: =IFERROR(__xludf.DUMMYFUNCTION("""COMPUTED_VALUE"""),"") | CN33: =IFERROR(__xludf.DUMMYFUNCTION("""COMPUTED_VALUE"""),"Chansey") -> Chansey | CO33: X
C34: zacian | D34: Zacian | CH34: =IFERROR(__xludf.DUMMYFUNCTION("""COMPUTED_VALUE"""),"") | CI34: =IFERROR(__xludf.DUMMYFUNCTION("""COMPUTED_VALUE"""),"Spiritomb") -> Spiritomb | CJ34: - | CM34: =IFERROR(__xludf.DUMMYFUNCTION("""COMPUTED_VALUE"""),"") | CN34: =IFERROR(__xludf.DUMMYFUNCTION("""COMPUTED_VALUE"""),"Charcadet") -> Charcadet | CO34: -
D35: Zacian-C | CH35: =IFERROR(__xludf.DUMMYFUNCTION("""COMPUTED_VALUE"""),"") | CI35: =IFERROR(__xludf.DUMMYFUNCTION("""COMPUTED_VALUE"""),"Toedscruel") -> Toedscruel | CJ35: - | CM35: =IFERROR(__xludf.DUMMYFUNCTION("""COMPUTED_VALUE"""),"") | CN35: =IFERROR(__xludf.DUMMYFUNCTION("""COMPUTED_VALUE"""),"Chewtle") -> Chewtle | CO35: -
C36: zamazenta | D36: Zamazenta | CH36: =IFERROR(__xludf.DUMMYFUNCTION("""COMPUTED_VALUE"""),"") | CI36: =IFERROR(__xludf.DUMMYFUNCTION("""COMPUTED_VALUE"""),"Toxtricity") -> Toxtricity | CJ36: - | CM36: =IFERROR(__xludf.DUMMYFUNCTION("""COMPUTED_VALUE"""),"") | CN36: =IFERROR(__xludf.DUMMYFUNCTION("""COMPUTED_VALUE"""),"Clauncher") -> Clauncher | CO36: -
D37: Zamazenta-C | CH37: =IFERROR(__xludf.DUMMYFUNCTION("""COMPUTED_VALUE"""),"") | CI37: =IFERROR(__xludf.DUMMYFUNCTION("""COMPUTED_VALUE"""),"Weavile") -> Weavile | CJ37: - | CM37: =IFERROR(__xludf.DUMMYFUNCTION("""COMPUTED_VALUE"""),"") | CN37: =IFERROR(__xludf.DUMMYFUNCTION("""COMPUTED_VALUE"""),"Clawitzer") -> Clawitzer | CO37: -
C38: zekrom | D38: Zekrom | CM38: =IFERROR(__xludf.DUMMYFUNCTION("""COMPUTED_VALUE"""),"") | CN38: =IFERROR(__xludf.DUMMYFUNCTION("""COMPUTED_VALUE"""),"Cloyster") -> Cloyster | CO38: -
D39: Zygarde-C | CM39: =IFERROR(__xludf.DUMMYFUNCTION("""COMPUTED_VALUE"""),"") | CN39: =IFERROR(__xludf.DUMMYFUNCTION("""COMPUTED_VALUE"""),"Combee") -> Combee | CO39: -
CM40: =IFERROR(__xludf.DUMMYFUNCTION("""COMPUTED_VALUE"""),"") | CN40: =IFERROR(__xludf.DUMMYFUNCTION("""COMPUTED_VALUE"""),"Copperajah") -> Copperajah | CO40: -
CM41: =IFERROR(__xludf.DUMMYFUNCTION("""COMPUTED_VALUE"""),"") | CN41: =IFERROR(__xludf.DUMMYFUNCTION("""COMPUTED_VALUE"""),"Corvisquire") -> Corvisquire | CO41: -
CM42: =IFERROR(__xludf.DUMMYFUNCTION("""COMPUTED_VALUE"""),"") | CN42: =IFERROR(__xludf.DUMMYFUNCTION("""COMPUTED_VALUE"""),"Crabominable") -> Crabominable | CO42: -
CM43: =IFERROR(__xludf.DUMMYFUNCTION("""COMPUTED_VALUE"""),"") | CN43: =IFERROR(__xludf.DUMMYFUNCTION("""COMPUTED_VALUE"""),"Crabrawler") -> Crabrawler | CO43: -
...

Sheet Teams
A1: vol
C3: =Source!G3 -> Jackson's Team | G3: =Source!G4 -> Zach's Team | K3: =Source!G5 -> Dick's Team | O3: =Source!G6 -> Ian's Team | S3: =Source!G7 -> Ryan's Team | W3: =Source!G8 -> Tyler's Team
C4: =Source!F3 -> Jackson McLoughlin | E4: =Source!I3 -> CST | G4: =Source!F4 -> Zach VanSickle | I4: =Source!I4 -> CST | K4: =Source!F5 -> Dick Hansen | M4: =Source!I5 -> EST | O4: =Source!F6 -> Ian Heslin | Q4: =Source!I6 -> CST | S4: =Source!F7 -> Ryan Tidey | U4: =Source!I7 -> EST | W4: =Source!F8 -> Tyler Gottfredsen | Y4: =Source!I8 -> CST
C5: {=IFERROR(VLOOKUP(D5:D15,{Pokedex!$I$2:$I534,Pokedex!$H$2:$H534},2,FALSE),"")} | D5: Gholdengo | E5: {=IFERROR(VLOOKUP(D5:D15,Source!$B$2:$C534,2,false),)} -> 15 | G5: {=IFERROR(VLOOKUP(H5:H15,{Pokedex!$I$2:$I534,Pokedex!$H$2:$H534},2,FALSE),"")} | H5: Annihilape | I5: {=IFERROR(VLOOKUP(H5:H15,Source!$B$2:$C534,2,false),)} -> 13 | K5: {=IFERROR(VLOOKUP(L5:L15,{Pokedex!$I$2:$I534,Pokedex!$H$2:$H534},2,FALSE),"")} | L5: Sylveon | M5: {=IFERROR(VLOOKUP(L5:L15,Source!$B$2:$C534,2,false),)} -> 13 | O5: {=IFERROR(VLOOKUP(P5:P15,{Pokedex!$I$2:$I534,Pokedex!$H$2:$H534},2,FALSE),"")} | P5: Murkrow | Q5: {=IFERROR(VLOOKUP(P5:P15,Source!$B$2:$C534,2,false),)} -> 12 | S5: {=IFERROR(VLOOKUP(T5:T15,{Pokedex!$I$2:$I534,Pokedex!$H$2:$H534},2,FALSE),"")} | T5: Hydreigon | U5: {=IFERROR(VLOOKUP(T5:T15,Source!$B$2:$C534,2,false),)} -> 12 | W5: {=IFERROR(VLOOKUP(X5:X15,{Pokedex!$I$2:$I534,Pokedex!$H$2:$H534},2,FALSE),"")} | X5: Dondozo | Y5: {=IFERROR(VLOOKUP(X5:X15,Source!$B$2:$C534,2,false),)} -> 12
D6: Paldean Tauros (Fire) | E6: 8 | H6: Maushold | I6: 10 | L6: Kingambit | M6: 10 | P6: Meowscarada | Q6: 15 | T6: Amoonguss | U6: 12 | X6: Tatsugiri | Y6: 12
D7: Kilowattrel | E7: 6 | H7: Armarouge | I7: 10 | L7: Volcarona | M7: 9 | P7: Garchomp | Q7: 10 | T7: Gengar | U7: 6 | X7: Dragonite | Y7: 9
D8: Farigiraf | E8: 6 | H8: Indeedee-Female | I8: 9 | L8: Pelipper | M8: 8 | P8: Arcanine | Q8: 9 | T8: Azumarill | U8: 9 | X8: Gallade | Y8: 6
D9: Quaquaval | E9: 5 | H9: Skeledirge | I9: 8 | L9: Palafin | M9: 8 | P9: Mimikyu | Q9: 8 | T9: Hariyama | U9: 6 | X9: Baxcalibur | Y9: 8
D10: Arboliva | E10: 4 | H10: Gastrodon | I10: 5 | L10: Pawmot | M10: 6 | P10: Gothitelle | Q10: 6 | T10: Oranguru | U10: 5 | X10: Talonflame | Y10: 9
D11: Garganacl | E11: 8 | H11: Dragapult | I11: 6 | L11: Lycanroc-Dusk | M11: 6 | P11: Scizor | Q11: 4 | T11: Orthworm | U11: 3 | X11: Tyranitar | Y11: 8
D12: Cetitan | E12: 4 | H12: Slaking | I12: 3 | L12: Raichu | M12: 3 | P12: Jolteon | Q12: 1 | T12: Torkoal | U12: 8 | X12: Lycanroc-Midday | Y12: 1
D13: Salamence | E13: 5 | H13: Grafaiai | I13: 3 | L13: Mudsdale | M13: 3 | P13: Espathra | Q13: 3 | T13: Chansey | U13: 1 | X13: Pachirisu | Y13: 3
D14: Abomasnow | E14: 5 | H14: Magnezone | I14: 3 | L14: Toxtricity | M14: 3 | P14: Rotom-Frost | Q14: 1 | T14: Lilligant | U14: 3 | X14: Azurill | Y14: 0
D15: Toxapex | E15: 4 | H15: Magikarp | I15: 0 | L15: Camerupt | M15: 1 | P15: Staraptor | Q15: 1 | T15: Flamigo | U15: 5 | X15: Gulpin | Y15: 0
C16: 1 FAs | D16: =70-SUM(E5:E15)&" points" -> 0 points | G16: 4 FAs | H16: =70-SUM(I5:I15)&" points" -> 0 points | K16: 5 FAs | L16: =70-SUM(M5:M15)&" points" -> 0 points | O16: 3 FAs | P16: =70-SUM(Q5:Q15)&" points" -> 0 points | S16: 2 FAs | T16: =70-SUM(U5:U15)&" points" -> 0 points | W16: 4 FAs | X16: =70-SUM(Y5:Y15)&" points" -> 2 points
D19: Coach | E19: Skips | H19: Timer
D20: {=Source!F3:F18} -> Jackson McLoughlin | E20: 1 | H20: =iferror(240/(2^E20), 240) -> 120
D21: Zach VanSickle | H21: =iferror(240/(2^E21), 240) -> 240
D22: Dick Hansen | E22: 2 | H22: =iferror(240/(2^E22), 240) -> 60
D23: Ian Heslin | H23: =iferror(240/(2^E23), 240) -> 240
D24: Ryan Tidey | H24: =iferror(240/(2^E24), 240) -> 240
D25: Tyler Gottfredsen | E25: 1 | H25: =iferror(240/(2^E25), 240) -> 120
H26: =iferror(240/(2^E26), 240) -> 240
H27: =iferror(240/(2^E27), 240) -> 240
H28: =iferror(240/(2^E28), 240) -> 240
H29: =iferror(240/(2^E29), 240) -> 240
H30: =iferror(240/(2^E30), 240) -> 240
H31: =iferror(240/(2^E31), 240) -> 240
H32: =iferror(240/(2^E32), 240) -> 240
H33: =iferror(240/(2^E33), 240) -> 240
H34: =iferror(240/(2^E34), 240) -> 240
H35: =iferror(240/(2^E35), 240) -> 240

Sheet Schedule
C4: Coach 1 | D4: W/L | E4: Diff | G4: W/L | H4: Coach 2
C6: Week 1
C7: {=Source!$P$3:$P$5} -> Zach VanSickle | D7: =Stats!$I$14 -> W | E7: 1 | F7: -1 | G7: =Stats!$J$14 -> L | H7: {=Source!$R$3:$R$5} -> Jackson McLoughlin
C8: Dick Hansen | D8: =Stats!$I$25 -> L | E8: =Stats!$D$23 -> -5 | F8: =Stats!$H$23 -> 5 | G8: =Stats!$J$25 -> W | H8: Ian Heslin
C9: Ryan Tidey | D9: =Stats!$I$36 -> W | E9: =Stats!$D$34 -> 3 | F9: =Stats!$H$34 -> -3 | G9: =Stats!$J$36 -> L | H9: Tyler Gottfredsen
C11: Week 2
C12: {=Source!$P$11:$P$13} -> Ryan Tidey | D12: =Stats!$R$14 -> L | E12: =Stats!$M$12 -> -5 | F12: =Stats!$Q$12 -> 5 | G12: =Stats!$S$14 -> W | H12: {=Source!$R$11:$R$13} -> Jackson McLoughlin
C13: Zach VanSickle | D13: =Stats!$R$25 -> W | E13: =Stats!$M$23 -> 9 | F13: =Stats!$Q$23 -> -9 | G13: =Stats!$S$25 -> L | H13: Dick Hansen
C14: Ian Heslin | D14: =Stats!$R$36 -> W | E14: =Stats!$M$34 -> 5 | F14: =Stats!$Q$34 -> -5 | G14: =Stats!$S$36 -> L | H14: Tyler Gottfredsen
C16: Week 3
C17: {=Source!$P$19:$P$21} -> Dick Hansen | D17: =Stats!$AA$14 -> L | E17: =Stats!$V$12 -> -5 | F17: =Stats!$Z$12 -> 5 | G17: =Stats!$AB$14 -> W | H17: {=Source!$R$19:$R$21} -> Jackson McLoughlin
C18: Zach VanSickle | D18: =Stats!$AA$25 -> L | E18: =Stats!$V$23 -> -4 | F18: =Stats!$Z$23 -> 4 | G18: =Stats!$AB$25 -> W | H18: Tyler Gottfredsen
C19: Ian Heslin | D19: =Stats!$AA$36 -> W | E19: =Stats!$V$34 -> 4 | F19: =Stats!$Z$34 -> -4 | G19: =Stats!$AB$36 -> L | H19: Ryan Tidey
C21: Week 4
C22: {=Source!$P$27:$P$30} -> Zach VanSickle | D22: =Stats!$AJ$14 -> L | E22: =Stats!$AE$12 -> 1 | F22: =Stats!$AI$12 -> -1 | G22: =Stats!$AK$14 -> W | H22: {=Source!$R$27:$R$30} -> Ryan Tidey
C23: Jackson McLoughlin | D23: =Stats!$AJ$25 -> L | E23: =Stats!$AE$23 -> -5 | F23: =Stats!$AI$23 -> 5 | G23: =Stats!$AK$25 -> W | H23: Ian Heslin
C24: Dick Hansen | D24: =Stats!$AJ$36 -> L | E24: =Stats!$AE$34 -> -7 | F24: =Stats!$AI$34 -> 7 | G24: =Stats!$AK$36 -> W | H24: Tyler Gottfredsen
C26: Week 5
C27: {=Source!$P$35:$P$37} -> Zach VanSickle | D27: W | E27: =Stats!$AN$12 -> 4 | F27: =Stats!$AR$12 -> -4 | G27: L | H27: {=Source!$R$35:$R$37} -> Jackson McLoughlin
C28: Dick Hansen | D28: =Stats!$AS$25 -> L | E28: =Stats!$AN$23 -> -5 | F28: =Stats!$AR$23 -> 5 | G28: =Stats!$AT$25 -> W | H28: Ryan Tidey
C29: Ian Heslin | D29: =Stats!$AS$36 -> W | E29: =Stats!$AN$34 -> 3 | F29: =Stats!$AR$34 -> -3 | G29: =Stats!$AT$36 -> L | H29: Tyler Gottfredsen
C31: Week 6
C32: {=Source!$P$43:$P$46} -> Zach VanSickle | D32: =Stats!$BB$14 -> W | E32: =Stats!$AW$12 -> 5 | F32: =Stats!$BA$12 -> -5 | G32: =Stats!$BC$14 -> L | H32: {=Source!$R$43:$R$46} -> Dick Hansen
C33: Jackson McLoughlin | D33: =Stats!$BB$25 -> L | E33: =Stats!$AW$23 -> -5 | F33: =Stats!$BA$23 -> 5 | G33: =Stats!$BC$25 -> W | H33: Tyler Gottfredsen
C34: Ian Heslin | D34: =Stats!$BB$36 -> W | E34: =Stats!$AW$34 -> 0 | F34: =Stats!$BA$34 -> 0 | G34: =Stats!$BC$36 -> L | H34: Ryan Tidey
C36: Week 7
C37: {=Source!$P$51:$P$54} -> Dick Hansen | D37: =Stats!$BK$14 -> L | E37: =Stats!$BF$12 -> -5 | F37: =Stats!$BJ$12 -> 5 | G37: =Stats!$BL$14 -> W | H37: {=Source!$R$51:$R$54} -> Jackson McLoughlin
C38: Zach VanSickle | D38: =Stats!$BK$25 -> L | E38: =Stats!$BF$23 -> -4 | F38: =Stats!$BJ$23 -> 4 | G38: =Stats!$BL$25 -> W | H38: Ian Heslin
C39: Ryan Tidey | D39: =Stats!$BK$36 -> L | E39: =Stats!$BF$34 -> 0 | F39: =Stats!$BJ$34 -> 0 | G39: =Stats!$BL$36 -> W | H39: Tyler Gottfredsen

Sheet Stats
C3: Week 1 | L3: Week 2 | U3: Week 3 | AD3: Week 4 | AM3: Week 5 | AV3: Week 6 | BE3: Week 7
C5: =Schedule!$C$7 -> Zach VanSickle | D5: K | E5: D | F5: Diff | G5: =Schedule!$H$7 -> Jackson McLoughlin | H5: K | I5: D | J5: Diff | L5: =Schedule!$C$12 -> Ryan Tidey | M5: K | N5: D | O5: Diff | P5: =Schedule!$H$12 -> Jackson McLoughlin | Q5: K | R5: D | S5: Diff | U5: =Schedule!$C$17 -> Dick Hansen | V5: K | W5: D | X5: Diff | Y5: =Schedule!$H$17 -> Jackson McLoughlin | Z5: K | AA5: D | AB5: Diff | AD5: =Schedule!$C$22 -> Zach VanSickle | AE5: K | AF5: D | AG5: Diff | AH5: =Schedule!$H$22 -> Ryan Tidey | AI5: K | AJ5: D | AK5: Diff | AM5: =Schedule!$C$27 -> Zach VanSickle | AN5: K | AO5: D | AP5: Diff | AQ5: =Schedule!$H$27 -> Jackson McLoughlin | AR5: K | AS5: D | AT5: Diff | AV5: =Schedule!$C$32 -> Zach VanSickle | AW5: K | AX5: D | AY5: Diff | AZ5: =Schedule!$H$32 -> Dick Hansen | BA5: K | BB5: D | BC5: Diff | BE5: =Schedule!$C$37 -> Dick Hansen | BF5: K | BG5: D | BH5: Diff | BI5: =Schedule!$H$37 -> Jackson McLoughlin | BJ5: K | BK5: D | BL5: Diff
C6: Annihilape | D6: 2 | E6: 2 | F6: =D6-E6 -> 0 | G6: Gholdengo | H6: 1 | I6: 2 | J6: =H6-I6 -> -1 | L6: Gengar | N6: 1 | O6: =M6-N6 -> -1 | P6: Kilowattrel | Q6: 1 | R6: 1 | S6: =Q6-R6 -> 0 | U6: Pawmot | W6: 2 | X6: =V6-W6 -> -2 | Y6: Abomasnow | Z6: 3 | AA6: 1 | AB6: =Z6-AA6 -> 2 | AD6: Dragapult | AE6: 1 | AF6: 1 | AG6: =AE6-AF6 -> 0 | AH6: Torkoal | AI6: 3 | AJ6: 3 | AK6: =AI6-AJ6 -> 0 | AM6: Magnezone | AN6: 4 | AO6: 1 | AP6: =AN6-AO6 -> 3 | AQ6: Abomasnow | AR6: 1 | AS6: 1 | AT6: =AR6-AS6 -> 0 | AW6: 5 | AY6: =AW6-AX6 -> 5 | BB6: 5 | BC6: =BA6-BB6 -> -5 | BG6: 5 | BH6: =BF6-BG6 -> -5 | BJ6: 5 | BL6: =BJ6-BK6 -> 5
C7: Maushold | E7: 1 | F7: =D7-E7 -> -1 | G7: Farigiraf | H7: 2 | I7: 2 | J7: =H7-I7 -> 0 | L7: Amoonguss | N7: 1 | O7: =M7-N7 -> -1 | P7: Gholdengo | Q7: 4 | R7: 1 | S7: =Q7-R7 -> 3 | U7: Kingambit | V7: 2 | W7: 2 | X7: =V7-W7 -> 0 | Y7: Kilowattrel | Z7: 1 | AA7: 1 | AB7: =Z7-AA7 -> 0 | AD7: Gastrodon | AE7: 2 | AF7: 2 | AG7: =AE7-AF7 -> 0 | AH7: Lilligant | AJ7: 2 | AK7: =AI7-AJ7 -> -2 | AM7: Slaking | AP7: =AN7-AO7 -> 0 | AQ7: Cetitan | AS7: 2 | AT7: =AR7-AS7 -> -2 | AY7: =AW7-AX7 -> 0 | BC7: =BA7-BB7 -> 0 | BH7: =BF7-BG7 -> 0 | BL7: =BJ7-BK7 -> 0
C8: Indeedee-Female | E8: 3 | F8: =D8-E8 -> -3 | G8: Kilowattrel | H8: 3 | I8: 3 | J8: =H8-I8 -> 0 | L8: Hydreigon | M8: 1 | N8: 2 | O8: =M8-N8 -> -1 | P8: Garganacl | S8: =Q8-R8 -> 0 | U8: Volcarona | V8: 1 | W8: 2 | X8: =V8-W8 -> -1 | Y8: Cetitan | AA8: 1 | AB8: =Z8-AA8 -> -1 | AD8: Slaking | AF8: 1 | AG8: =AE8-AF8 -> -1 | AH8: Oranguru | AJ8: 1 | AK8: =AI8-AJ8 -> -1 | AM8: Grafaiai | AP8: =AN8-AO8 -> 0 | AQ8: Gholdengo | AR8: 2 | AS8: 2 | AT8: =AR8-AS8 -> 0 | AY8: =AW8-AX8 -> 0 | BC8: =BA8-BB8 -> 0 | BH8: =BF8-BG8 -> 0 | BL8: =BJ8-BK8 -> 0
C9: Magnezone | D9: 3 | F9: =D9-E9 -> 3 | G9: Garganacl | H9: 3 | I9: 1 | J9: =H9-I9 -> 2 | L9: Chansey | M9: 1 | N9: 2 | O9: =M9-N9 -> -1 | P9: Arboliva | S9: =Q9-R9 -> 0 | U9: Sylveon | V9: 1 | W9: 2 | X9: =V9-W9 -> -1 | Y9: Armarouge | AA9: 1 | AB9: =Z9-AA9 -> -1 | AD9: Grafaiai | AF9: 1 | AG9: =AE9-AF9 -> -1 | AH9: Hariyama | AJ9: 1 | AK9: =AI9-AJ9 -> -1 | AM9: Gastrodon | AN9: 3 | AO9: 3 | AP9: =AN9-AO9 -> 0 | AQ9: Toxapex | AS9: 2 | AT9: =AR9-AS9 -> -2 | AY9: =AW9-AX9 -> 0 | BC9: =BA9-BB9 -> 0 | BH9: =BF9-BG9 -> 0 | BL9: =BJ9-BK9 -> 0
C10: Gastrodon | D10: 4 | E10: 2 | F10: =D10-E10 -> 2 | G10: Armarouge | I10: 1 | J10: =H10-I10 -> -1 | L10: Azumarill | N10: 1 | O10: =M10-N10 -> -1 | P10: Armarouge | Q10: 3 | S10: =Q10-R10 -> 3 | U10: Pelipper | X10: =V10-W10 -> 0 | Y10: Quaquaval | AB10: =Z10-AA10 -> 0 | AD10: Indeedee-Female | AF10: 1 | AG10: =AE10-AF10 -> -1 | AH10: Flamigo | AI10: 3 | AJ10: 1 | AK10: =AI10-AJ10 -> 2 | AM10: Dragapult | AN10: 2 | AO10: 1 | AP10: =AN10-AO10 -> 1 | AQ10: Kilowattrel | AS10: 2 | AT10: =AR10-AS10 -> -2 | AY10: =AW10-AX10 -> 0 | BC10: =BA10-BB10 -> 0 | BH10: =BF10-BG10 -> 0 | BL10: =BJ10-BK10 -> 0
C11: Dragapult | D11: 2 | E11: 2 | F11: =D11-E11 -> 0 | G11: Arboliva | I11: 1 | J11: =H11-I11 -> -1 | L11: Orthworm | M11: 1 | N11: 1 | O11: =M11-N11 -> 0 | P11: Farigiraf | R11: 1 | S11: =Q11-R11 -> -1 | U11: Palafin | W11: 1 | X11: =V11-W11 -> -1 | Y11: Gholdengo | Z11: 5 | AB11: =Z11-AA11 -> 5 | AD11: Skeledirge | AE11: 6 | AF11: 2 | AG11: =AE11-AF11 -> 4 | AH11: Azumarill | AI11: 2 | AJ11: 1 | AK11: =AI11-AJ11 -> 1 | AM11: Skeledirge | AN11: 2 | AO11: 2 | AP11: =AN11-AO11 -> 0 | AQ11: Garganacl | AR11: 4 | AS11: 2 | AT11: =AR11-AS11 -> 2 | AY11: =AW11-AX11 -> 0 | BC11: =BA11-BB11 -> 0 | BH11: =BF11-BG11 -> 0 | BL11: =BJ11-BK11 -> 0
C12: Differential | D12: =SUM(F6:F11) -> 1 | G12: Differential | H12: =SUM(J6:J11) -> -1 | L12: Differential | M12: =SUM(O6:O11) -> -5 | P12: Differential | Q12: =SUM(S6:S11) -> 5 | U12: Differential | V12: =SUM(X6:X11) -> -5 | Y12: Differential | Z12: =SUM(AB6:AB11) -> 5 | AD12: Differential | AE12: =SUM(AG6:AG11) -> 1 | AH12: Differential | AI12: =SUM(AK6:AK11) -> -1 | AM12: Differential | AN12: =SUM(AP6:AP11) -> 4 | AQ12: Differential | AR12: =SUM(AT6:AT11) -> -4 | AV12: Differential | AW12: =SUM(AY6:AY11) -> 5 | AZ12: Differential | BA12: =SUM(BC6:BC11) -> -5 | BE12: Differential | BF12: =SUM(BH6:BH11) -> -5 | BI12: Differential | BJ12: =SUM(BL6:BL11) -> 5
C13: Games Won | D13: 2 | G13: Games Won | H13: 1 | L13: Games Won | M13: 0 | P13: Games Won | Q13: 2 | U13: Games Won | V13: 0 | Y13: Games Won | Z13: 2 | AD13: Games Won | AE13: 1 | AH13: Games Won | AI13: 2 | AM13: Games Won | AN13: 2 | AQ13: Games Won | AR13: 1 | AV13: Games Won | AW13: 2 | AZ13: Games Won | BA13: 1 | BE13: Games Won | BF13: 1 | BI13: Games Won | BJ13: 2
C14: Replays | D14: 1 | E14: 2 | F14: 3 | G14: Series Outcome | I14: =IF(D13=2,"W",IF(H13=2,"L",)) -> W | J14: =IF(H13=2,"W",IF(D13=2,"L",)) -> L | L14: Replays | M14: 1 | N14: 2 | O14: 3 | P14: Series Outcome | R14: =IF(M13=2,"W",IF(Q13=2,"L",)) -> L | S14: =IF(Q13=2,"W",IF(M13=2,"L",)) -> W | U14: Replays | V14: 1 | W14: 2 | X14: 3 | Y14: Series Outcome | AA14: =IF(V13=2,"W",IF(Z13=2,"L",)) -> L | AB14: =IF(Z13=2,"W",IF(V13=2,"L",)) -> W | AD14: Replays | AE14: 1 | AF14: 2 | AG14: 3 | AH14: Series Outcome | AJ14: =IF(AE13=2,"W",IF(AI13=2,"L",)) -> L | AK14: =IF(AI13=2,"W",IF(AE13=2,"L",)) -> W | AM14: Replays | AN14: 1 | AO14: 2 | AP14: 3 | AQ14: Series Outcome | AS14: =IF(AN13=2,"W",IF(AR13=2,"L",)) -> W | AT14: =IF(AR13=2,"W",IF(AN13=2,"L",)) -> L | AV14: Replays | AW14: 1 | AX14: 2 | AY14: 3 | AZ14: Series Outcome | BB14: =IF(AW13=2,"W",IF(BA13=2,"L",)) -> W | BC14: =IF(BA13=2,"W",IF(AW13=2,"L",)) -> L | BE14: Replays | BF14: 1 | BG14: 2 | BH14: 3 | BI14: Series Outcome | BK14: =IF(BF13=2,"W",IF(BJ13=2,"L",)) -> L | BL14: =IF(BJ13=2,"W",IF(BF13=2,"L",)) -> W
C16: =Schedule!$C$8 -> Dick Hansen | D16: K | E16: D | F16: Diff | G16: =Schedule!$H$8 -> Ian Heslin | H16: K | I16: D | J16: Diff | L16: =Schedule!$C$13 -> Zach VanSickle | M16: K | N16: D | O16: Diff | P16: =Schedule!$H$13 -> Dick Hansen | Q16: K | R16: D | S16: Diff | U16: =Schedule!$C$18 -> Zach VanSickle | V16: K | W16: D | X16: Diff | Y16: =Schedule!$H$18 -> Tyler Gottfredsen | Z16: K | AA16: D | AB16: Diff | AD16: =Schedule!$C$23 -> Jackson McLoughlin | AE16: K | AF16: D | AG16: Diff | AH16: =Schedule!$H$23 -> Ian Heslin | AI16: K | AJ16: D | AK16: Diff | AM16: =Schedule!$C$28 -> Dick Hansen | AN16: K | AO16: D | AP16: Diff | AQ16: =Schedule!$H$28 -> Ryan Tidey | AR16: K | AS16: D | AT16: Diff | AV16: =Schedule!$C$33 -> Jackson McLoughlin | AW16: K | AX16: D | AY16: Diff | AZ16: =Schedule!$H$33 -> Tyler Gottfredsen | BA16: K | BB16: D | BC16: Diff | BE16: =Schedule!$C$38 -> Zach VanSickle | BF16: K | BG16: D | BH16: Diff | BI16: =Schedule!$H$38 -> Ian Heslin | BJ16: K | BK16: D | BL16: Diff
C17: Pelipper | D17: 1 | E17: 1 | F17: =D17-E17 -> 0 | G17: Garchomp | H17: 3 | I17: 1 | J17: =H17-I17 -> 2 | L17: Magnezone | M17: 3 | O17: =M17-N17 -> 3 | P17: Palafin | R17: 3 | S17: =Q17-R17 -> -3 | U17: Magnezone | V17: 3 | W17: 1 | X17: =V17-W17 -> 2 | Y17: Dondozo | Z17: 2 | AA17: 2 | AB17: =Z17-AA17 -> 0 | AD17: Abomasnow | AF17: 1 | AG17: =AE17-AF17 -> -1 | AH17: Murkrow | AI17: 3 | AJ17: 1 | AK17: =AI17-AJ17 -> 2 | AO17: 5 | AP17: =AN17-AO17 -> -5 | AR17: 5 | AT17: =AR17-AS17 -> 5 | AV17: Cetitan | AW17: 2 | AX17: 1 | AY17: =AW17-AX17 -> 1 | AZ17: Dondozo | BC17: =BA17-BB17 -> 0 | BE17: Grafaiai | BG17: 1 | BH17: =BF17-BG17 -> -1 | BI17: Gothitelle | BJ17: 3 | BK17: 2 | BL17: =BJ17-BK17 -> 1
C18: Sylveon | D18: 1 | E18: 1 | F18: =D18-E18 -> 0 | G18: Meowscarada | H18: 2 | I18: 2 | J18: =H18-I18 -> 0 | L18: Annihilape | M18: 1 | O18: =M18-N18 -> 1 | P18: Pelipper | R18: 1 | S18: =Q18-R18 -> -1 | U18: Gastrodon | W18: 2 | X18: =V18-W18 -> -2 | Y18: Tatsugiri | Z18: 1 | AA18: 1 | AB18: =Z18-AA18 -> 0 | AD18: Kilowattrel | AF18: 1 | AG18: =AE18-AF18 -> -1 | AH18: Garchomp | AI18: 3 | AJ18: 1 | AK18: =AI18-AJ18 -> 2 | AP18: =AN18-AO18 -> 0 | AT18: =AR18-AS18 -> 0 | AV18: Garganacl | AW18: 1 | AX18: 2 | AY18: =AW18-AX18 -> -1 | AZ18: Tatsugiri | BC18: =BA18-BB18 -> 0 | BE18: Slaking | BF18: 1 | BG18: 1 | BH18: =BF18-BG18 -> 0 | BI18: Meowscarada | BJ18: 1 | BK18: 1 | BL18: =BJ18-BK18 -> 0
C19: Palafin | E19: 2 | F19: =D19-E19 -> -2 | G19: Jolteon | H19: 3 | I19: 1 | J19: =H19-I19 -> 2 | L19: Indeedee-Female | M19: 2 | O19: =M19-N19 -> 2 | P19: Kingambit | R19: 1 | S19: =Q19-R19 -> -1 | U19: Dragapult | W19: 1 | X19: =V19-W19 -> -1 | Y19: Dragonite | AB19: =Z19-AA19 -> 0 | AD19: Gholdengo | AE19: 1 | AF19: 1 | AG19: =AE19-AF19 -> 0 | AH19: Scizor | AI19: 1 | AK19: =AI19-AJ19 -> 1 | AP19: =AN19-AO19 -> 0 | AT19: =AR19-AS19 -> 0 | AV19: Kilowattrel | AX19: 1 | AY19: =AW19-AX19 -> -1 | AZ19: Dragonite | BA19: 1 | BC19: =BA19-BB19 -> 1 | BE19: Dragapult | BF19: 1 | BG19: 2 | BH19: =BF19-BG19 -> -1 | BI19: Murkrow | BJ19: 4 | BK19: 1 | BL19: =BJ19-BK19 -> 3
C20: Kingambit | E20: 1 | F20: =D20-E20 -> -1 | G20: Arcanine | H20: 1 | J20: =H20-I20 -> 1 | L20: Slaking | M20: 4 | O20: =M20-N20 -> 4 | P20: Pawmot | R20: 2 | S20: =Q20-R20 -> -2 | U20: Slaking | V20: 1 | W20: 1 | X20: =V20-W20 -> 0 | Y20: Pachirisu | AB20: =Z20-AA20 -> 0 | AD20: Glimmora | AF20: 1 | AG20: =AE20-AF20 -> -1 | AH20: Meowscarada | AK20: =AI20-AJ20 -> 0 | AP20: =AN20-AO20 -> 0 | AT20: =AR20-AS20 -> 0 | AV20: Abomasnow | AX20: 1 | AY20: =AW20-AX20 -> -1 | AZ20: Talonflame | BB20: 1 | BC20: =BA20-BB20 -> -1 | BE20: Gastrodon | BF20: 2 | BG20: 2 | BH20: =BF20-BG20 -> 0 | BI20: Garchomp | BJ20: 1 | BK20: 1 | BL20: =BJ20-BK20 -> 0
C21: Volcarona | D21: 1 | E21: 2 | F21: =D21-E21 -> -1 | G21: Murkrow | J21: =H21-I21 -> 0 | L21: Grafaiai | N21: 1 | O21: =M21-N21 -> -1 | P21: Sylveon | R21: 2 | S21: =Q21-R21 -> -2 | U21: Grafaiai | W21: 1 | X21: =V21-W21 -> -1 | Y21: Tyranitar | Z21: 4 | AB21: =Z21-AA21 -> 4 | AD21: Garganacl | AE21: 2 | AF21: 2 | AG21: =AE21-AF21 -> 0 | AH21: Arcanine | AK21: =AI21-AJ21 -> 0 | AP21: =AN21-AO21 -> 0 | AT21: =AR21-AS21 -> 0 | AV21: Gholdengo | AX21: 1 | AY21: =AW21-AX21 -> -1 | AZ21: Baxcalibur | BA21: 3 | BC21: =BA21-BB21 -> 3 | BE21: Indeedee-Female | BG21: 1 | BH21: =BF21-BG21 -> -1 | BI21: Scizor | BL21: =BJ21-BK21 -> 0
C22: Pawmot | D22: 1 | E22: 2 | F22: =D22-E22 -> -1 | G22: Staraptor | J22: =H22-I22 -> 0 | L22: Maushold | O22: =M22-N22 -> 0 | P22: Volcarona | Q22: 1 | R22: 1 | S22: =Q22-R22 -> 0 | U22: Skeledirge | W22: 2 | X22: =V22-W22 -> -2 | Y22: Lycanroc-Midday | Z22: 1 | AA22: 1 | AB22: =Z22-AA22 -> 0 | AD22: Farigiraf | AF22: 2 | AG22: =AE22-AF22 -> -2 | AH22: Jolteon | AK22: =AI22-AJ22 -> 0 | AP22: =AN22-AO22 -> 0 | AT22: =AR22-AS22 -> 0 | AV22: Toxapex | AX22: 2 | AY22: =AW22-AX22 -> -2 | AZ22: Gallade | BA22: 3 | BB22: 1 | BC22: =BA22-BB22 -> 2 | BE22: Armarouge | BG22: 1 | BH22: =BF22-BG22 -> -1 | BI22: Mimikyu | BL22: =BJ22-BK22 -> 0
C23: Differential | D23: =SUM(F17:F22) -> -5 | G23: Differential | H23: =SUM(J17:J22) -> 5 | L23: Differential | M23: =SUM(O17:O22) -> 9 | P23: Differential | Q23: =SUM(S17:S22) -> -9 | U23: Differential | V23: =SUM(X17:X22) -> -4 | Y23: Differential | Z23: =SUM(AB17:AB22) -> 4 | AD23: Differential | AE23: =SUM(AG17:AG22) -> -5 | AH23: Differential | AI23: =SUM(AK17:AK22) -> 5 | AM23: Differential | AN23: =SUM(AP17:AP22) -> -5 | AQ23: Differential | AR23: =SUM(AT17:AT22) -> 5 | AV23: Differential | AW23: =SUM(AY17:AY22) -> -5 | AZ23: Differential | BA23: =SUM(BC17:BC22) -> 5 | BE23: Differential | BF23: =SUM(BH17:BH22) -> -4 | BI23: Differential | BJ23: =SUM(BL17:BL22) -> 4
C24: Games Won | D24: 0 | G24: Games Won | H24: 2 | L24: Games Won | M24: 2 | P24: Games Won | Q24: 0 | U24: Games Won | V24: 0 | Y24: Games Won | Z24: 2 | AD24: Games Won | AE24: 0 | AH24: Games Won | AI24: 2 | AM24: Games Won | AN24: 1 | AQ24: Games Won | AR24: 2 | AV24: Games Won | AW24: 0 | AZ24: Games Won | BA24: 2 | BE24: Games Won | BF24: 0 | BI24: Games Won | BJ24: 2
C25: Replays | D25: 1 | E25: 2 | F25: 3 | G25: Series Outcome | I25: =IF(D24=2,"W",IF(H24=2,"L",)) -> L | J25: =IF(H24=2,"W",IF(D24=2,"L",)) -> W | L25: Replays | M25: 1 | N25: 2 | O25: 3 | P25: Series Outcome | R25: =IF(M24=2,"W",IF(Q24=2,"L",)) -> W | S25: =IF(Q24=2,"W",IF(M24=2,"L",)) -> L | U25: Replays | V25: 1 | W25: 2 | X25: 3 | Y25: Series Outcome | AA25: =IF(V24=2,"W",IF(Z24=2,"L",)) -> L | AB25: =IF(Z24=2,"W",IF(V24=2,"L",)) -> W | AD25: Replays | AE25: 1 | AF25: 2 | AG25: 3 | AH25: Series Outcome | AJ25: =IF(AE24=2,"W",IF(AI24=2,"L",)) -> L | AK25: =IF(AI24=2,"W",IF(AE24=2,"L",)) -> W | AM25: Replays | AN25: 1 | AO25: 2 | AP25: 3 | AQ25: Series Outcome | AS25: =IF(AN24=2,"W",IF(AR24=2,"L",)) -> L | AT25: =IF(AR24=2,"W",IF(AN24=2,"L",)) -> W | AV25: Replays | AW25: 1 | AX25: 2 | AY25: 3 | AZ25: Series Outcome | BB25: =IF(AW24=2,"W",IF(BA24=2,"L",)) -> L | BC25: =IF(BA24=2,"W",IF(AW24=2,"L",)) -> W | BE25: Replays | BF25: 1 | BG25: 2 | BH25: 3 | BI25: Series Outcome | BK25: =IF(BF24=2,"W",IF(BJ24=2,"L",)) -> L | BL25: =IF(BJ24=2,"W",IF(BF24=2,"L",)) -> W
C27: =Schedule!$C$9 -> Ryan Tidey | D27: K | E27: D | F27: Diff | G27: =Schedule!$H$9 -> Tyler Gottfredsen | H27: K | I27: D | J27: Diff | L27: =Schedule!$C$14 -> Ian Heslin | M27: K | N27: D | O27: Diff | P27: =Schedule!$H$14 -> Tyler Gottfredsen | Q27: K | R27: D | S27: Diff | U27: =Schedule!$C$19 -> Ian Heslin | V27: K | W27: D | X27: Diff | Y27: =Schedule!$H$19 -> Ryan Tidey | Z27: K | AA27: D | AB27: Diff | AD27: =Schedule!$C$24 -> Dick Hansen | AE27: K | AF27: D | AG27: Diff | AH27: =Schedule!$H$24 -> Tyler Gottfredsen | AI27: K | AJ27: D | AK27: Diff | AM27: =Schedule!$C$29 -> Ian Heslin | AN27: K | AO27: D | AP27: Diff | AQ27: =Schedule!$H$29 -> Tyler Gottfredsen | AR27: K | AS27: D | AT27: Diff | AV27: =Schedule!$C$34 -> Ian Heslin | AW27: K | AX27: D | AY27: Diff | AZ27: =Schedule!$H$34 -> Ryan Tidey | BA27: K | BB27: D | BC27: Diff | BE27: =Schedule!$C$39 -> Ryan Tidey | BF27: K | BG27: D | BH27: Diff | BI27: =Schedule!$H$39 -> Tyler Gottfredsen | BJ27: K | BK27: D | BL27: Diff
C28: Amoonguss | D28: 2 | E28: 2 | F28: =D28-E28 -> 0 | G28: Dondozo | I28: 2 | J28: =H28-I28 -> -2 | L28: Meowscarada | M28: 3 | N28: 1 | O28: =M28-N28 -> 2 | P28: Dondozo | R28: 2 | S28: =Q28-R28 -> -2 | U28: Arcanine | V28: 5 | X28: =V28-W28 -> 5 | Y28: Hydreigon | Z28: 1 | AA28: 2 | AB28: =Z28-AA28 -> -1 | AD28: Sylveon | AE28: 1 | AF28: 2 | AG28: =AE28-AF28 -> -1 | AH28: Dondozo | AI28: 5 | AJ28: 1 | AK28: =AI28-AJ28 -> 4 | AM28: Gothitelle | AN28: 1 | AO28: 1 | AP28: =AN28-AO28 -> 0 | AQ28: Talonflame | AS28: 2 | AT28: =AR28-AS28 -> -2 | AV28: Arcanine | AW28: 2 | AX28: 1 | AY28: =AW28-AX28 -> 1 | AZ28: Hariyama | BA28: 1 | BB28: 1 | BC28: =BA28-BB28 -> 0 | BH28: =BF28-BG28 -> 0 | BL28: =BJ28-BK28 -> 0
C29: Hydreigon | E29: 1 | F29: =D29-E29 -> -1 | G29: Tatsugiri | H29: 1 | I29: 1 | J29: =H29-I29 -> 0 | L29: Garchomp | M29: 1 | O29: =M29-N29 -> 1 | P29: Tatsugiri | R29: 2 | S29: =Q29-R29 -> -2 | U29: Staraptor | V29: 2 | W29: 2 | X29: =V29-W29 -> 0 | Y29: Amoonguss | AA29: 1 | AB29: =Z29-AA29 -> -1 | AD29: Kingambit | AF29: 1 | AG29: =AE29-AF29 -> -1 | AH29: Talonflame | AJ29: 1 | AK29: =AI29-AJ29 -> -1 | AM29: Meowscarada | AN29: 2 | AO29: 1 | AP29: =AN29-AO29 -> 1 | AQ29: Dondozo | AR29: 2 | AS29: 2 | AT29: =AR29-AS29 -> 0 | AV29: Staraptor | AW29: 1 | AX29: 3 | AY29: =AW29-AX29 -> -2 | AZ29: Oranguru | BB29: 1 | BC29: =BA29-BB29 -> -1 | BH29: =BF29-BG29 -> 0 | BL29: =BJ29-BK29 -> 0
C30: Gengar | F30: =D30-E30 -> 0 | G30: Dragonite | H30: 4 | I30: 2 | J30: =H30-I30 -> 2 | L30: Murkrow | N30: 1 | O30: =M30-N30 -> -1 | P30: Dragonite | Q30: 2 | R30: 2 | S30: =Q30-R30 -> 0 | U30: Meowscarada | W30: 1 | X30: =V30-W30 -> -1 | Y30: Azumarill | AA30: 1 | AB30: =Z30-AA30 -> -1 | AD30: Volcarona | AF30: 2 | AG30: =AE30-AF30 -> -2 | AH30: Tatsugiri | AI30: 1 | AK30: =AI30-AJ30 -> 1 | AM30: Murkrow | AO30: 2 | AP30: =AN30-AO30 -> -2 | AQ30: Tyranitar | AT30: =AR30-AS30 -> 0 | AV30: Meowscarada | AW30: 4 | AX30: 2 | AY30: =AW30-AX30 -> 2 | AZ30: Azumarill | BA30: 1 | BB30: 2 | BC30: =BA30-BB30 -> -1 | BH30: =BF30-BG30 -> 0 | BL30: =BJ30-BK30 -> 0
C31: Orthworm | D31: 1 | E31: 1 | F31: =D31-E31 -> 0 | G31: Pachirisu | I31: 3 | J31: =H31-I31 -> -3 | L31: Mimikyu | M31: 4 | N31: 1 | O31: =M31-N31 -> 3 | P31: Tyranitar | S31: =Q31-R31 -> 0 | U31: Garchomp | V31: 1 | W31: 1 | X31: =V31-W31 -> 0 | Y31: Hariyama | Z31: 2 | AA31: 2 | AB31: =Z31-AA31 -> 0 | AD31: Pawmot | AE31: 1 | AF31: 2 | AG31: =AE31-AF31 -> -1 | AH31: Dragonite | AI31: 3 | AK31: =AI31-AJ31 -> 3 | AM31: Garchomp | AN31: 5 | AP31: =AN31-AO31 -> 5 | AQ31: Dragonite | AR31: 3 | AS31: 2 | AT31: =AR31-AS31 -> 1 | AV31: Garchomp | AW31: 2 | AX31: 1 | AY31: =AW31-AX31 -> 1 | AZ31: Torkoal | BA31: 6 | BB31: 2 | BC31: =BA31-BB31 -> 4 | BH31: =BF31-BG31 -> 0 | BL31: =BJ31-BK31 -> 0
C32: Azumarill | D32: 5 | E32: 2 | F32: =D32-E32 -> 3 | G32: Tyranitar | H32: 1 | I32: 1 | J32: =H32-I32 -> 0 | L32: Bronzong | O32: =M32-N32 -> 0 | P32: Hatterene | Q32: 1 | R32: 2 | S32: =Q32-R32 -> -1 | U32: Murkrow | X32: =V32-W32 -> 0 | Y32: Ceruledge | AA32: 1 | AB32: =Z32-AA32 -> -1 | AD32: Palafin | AF32: 2 | AG32: =AE32-AF32 -> -2 | AH32: Tyranitar | AK32: =AI32-AJ32 -> 0 | AM32: Espathra | AO32: 1 | AP32: =AN32-AO32 -> -1 | AQ32: Tatsugiri | AS32: 2 | AT32: =AR32-AS32 -> -2 | AV32: Murkrow | AX32: 2 | AY32: =AW32-AX32 -> -2 | AZ32: Lilligant | BA32: 1 | BB32: 2 | BC32: =BA32-BB32 -> -1 | BH32: =BF32-BG32 -> 0 | BL32: =BJ32-BK32 -> 0
